Workbook
Name 顧客データベース20250213140013_0: コミュおまとめ!$A$1:$I$691
Name 顧客データベース20250213140013_0: 'まとめ継続(1月)'!$B$1:$J$691

Sheet Sheet11
A1: タイプ1 | B1: タイプ2 | C1: 商品名 | D1: 計上月 | E1: 合計金額 | F1: N
A2: まとめ継続 | B2: 全体売上 | C2: 3ヶ月会員（ライト・クレカ自動更新） | D2: 46143 | E2: 0 | F2: 1
A3: まとめ継続 | B3: 全体売上 | C3: 3ヶ月会員（ライト・クレカ自動更新） | D3: 46174 | E3: 79200 | F3: 2
A4: まとめ継続 | B4: 全体売上 | C4: 3ヶ月会員（ライト・クレカ自動更新） | D4: 46204 | E4: 1683000 | F4: 3
A5: まとめ継続 | B5: 全体売上 | C5: 3ヶ月会員（ライト・クレカ自動更新） | D5: 46235 | E5: 1881000 | F5: 4
A6: まとめ継続 | B6: 全体売上 | C6: 3ヶ月会員（ライト・クレカ自動更新） | D6: 46266 | E6: 1801800 | F6: 5
A7: まとめ継続 | B7: 全体売上 | C7: 3ヶ月会員（ライト・クレカ自動更新） | D7: 46296 | E7: 198000 | F7: 6
A8: まとめ継続 | B8: 全体売上 | C8: 3ヶ月会員（ライト・クレカ自動更新） | D8: 46327 | E8: 0 | F8: 7
A9: まとめ継続 | B9: 全体売上 | C9: 3ヶ月会員（ライト・クレカ自動更新） | D9: 46357 | E9: 0 | F9: 8
A10: まとめ継続 | B10: 全体売上 | C10: 3ヶ月会員（ライト・クレカ自動更新） | D10: 46388 | E10: 0 | F10: 9
A11: まとめ継続 | B11: 全体売上 | C11: 3ヶ月会員（ライト・クレカ自動更新） | D11: 46419 | E11: 0 | F11: 10
A12: まとめ継続 | B12: 全体売上 | C12: 3ヶ月会員（ライト・クレカ自動更新） | D12: 46447 | E12: 0 | F12: 11
A13: まとめ継続 | B13: 全体売上 | C13: 3ヶ月会員（ライト・クレカ自動更新） | D13: 46478 | E13: 0 | F13: 12
... A265: まとめ継続 | B265: 自社分 | C265: 銀振会員（更新要ｶｸﾆﾝ）Apex年間 | D265: 46784 | E265: 0 | F265: 264

Sheet Sheet11 (3月)
A1: タイプ1 | B1: タイプ2 | C1: 商品名 | D1: 計上月 | E1: 合計金額 | F1: N
A2: まとめ継続 | B2: 全体売上 | C2: 3ヶ月会員（ライト・クレカ自動更新） | D2: 46113 | E2: 0 | F2: 1
A3: まとめ継続 | B3: 全体売上 | C3: 3ヶ月会員（ライト・クレカ自動更新） | D3: 46143 | E3: 277200 | F3: 2
A4: まとめ継続 | B4: 全体売上 | C4: 3ヶ月会員（ライト・クレカ自動更新） | D4: 46174 | E4: 356400 | F4: 3
A5: まとめ継続 | B5: 全体売上 | C5: 3ヶ月会員（ライト・クレカ自動更新） | D5: 46204 | E5: 1960200 | F5: 4
A6: まとめ継続 | B6: 全体売上 | C6: 3ヶ月会員（ライト・クレカ自動更新） | D6: 46235 | E6: 1702800 | F6: 5
A7: まとめ継続 | B7: 全体売上 | C7: 3ヶ月会員（ライト・クレカ自動更新） | D7: 46266 | E7: 1623600 | F7: 6
A8: まとめ継続 | B8: 全体売上 | C8: 3ヶ月会員（ライト・クレカ自動更新） | D8: 46296 | E8: 19800 | F8: 7
A9: まとめ継続 | B9: 全体売上 | C9: 3ヶ月会員（ライト・クレカ自動更新） | D9: 46327 | E9: 0 | F9: 8
A10: まとめ継続 | B10: 全体売上 | C10: 3ヶ月会員（ライト・クレカ自動更新） | D10: 46357 | E10: 0 | F10: 9
A11: まとめ継続 | B11: 全体売上 | C11: 3ヶ月会員（ライト・クレカ自動更新） | D11: 46388 | E11: 0 | F11: 10
A12: まとめ継続 | B12: 全体売上 | C12: 3ヶ月会員（ライト・クレカ自動更新） | D12: 46419 | E12: 0 | F12: 11
A13: まとめ継続 | B13: 全体売上 | C13: 3ヶ月会員（ライト・クレカ自動更新） | D13: 46447 | E13: 0 | F13: 12
... A265: まとめ継続 | B265: 自社分 | C265: 銀振会員（更新要ｶｸﾆﾝ）Apex年間 | D265: 46753 | E265: 0 | F265: 264

Sheet Sheet11 (2月)
A1: タイプ1 | B1: タイプ2 | C1: 商品名 | D1: 計上月 | E1: 合計金額 | F1: N
A2: まとめ継続 | B2: 全体売上 | C2: 3ヶ月会員（ライト・クレカ自動更新） | D2: 46082 | E2: 0 | F2: 1
A3: まとめ継続 | B3: 全体売上 | C3: 3ヶ月会員（ライト・クレカ自動更新） | D3: 46113 | E3: 1663200 | F3: 2
A4: まとめ継続 | B4: 全体売上 | C4: 3ヶ月会員（ライト・クレカ自動更新） | D4: 46143 | E4: 2118600 | F4: 3
A5: まとめ継続 | B5: 全体売上 | C5: 3ヶ月会員（ライト・クレカ自動更新） | D5: 46174 | E5: 2197800 | F5: 4
A6: まとめ継続 | B6: 全体売上 | C6: 3ヶ月会員（ライト・クレカ自動更新） | D6: 46204 | E6: 534600 | F6: 5
A7: まとめ継続 | B7: 全体売上 | C7: 3ヶ月会員（ライト・クレカ自動更新） | D7: 46235 | E7: 79200 | F7: 6
A8: まとめ継続 | B8: 全体売上 | C8: 3ヶ月会員（ライト・クレカ自動更新） | D8: 46266 | E8: 0 | F8: 7
A9: まとめ継続 | B9: 全体売上 | C9: 3ヶ月会員（ライト・クレカ自動更新） | D9: 46296 | E9: 0 | F9: 8
A10: まとめ継続 | B10: 全体売上 | C10: 3ヶ月会員（ライト・クレカ自動更新） | D10: 46327 | E10: 0 | F10: 9
A11: まとめ継続 | B11: 全体売上 | C11: 3ヶ月会員（ライト・クレカ自動更新） | D11: 46357 | E11: 0 | F11: 10
A12: まとめ継続 | B12: 全体売上 | C12: 3ヶ月会員（ライト・クレカ自動更新） | D12: 46388 | E12: 0 | F12: 11
A13: まとめ継続 | B13: 全体売上 | C13: 3ヶ月会員（ライト・クレカ自動更新） | D13: 46419 | E13: 0 | F13: 12
... A265: まとめ継続 | B265: 自社分 | C265: 銀振会員（更新要ｶｸﾆﾝ）Apex年間 | D265: 46722 | E265: 0 | F265: 264

Sheet Sheet11 (1月)
A1: タイプ1 | B1: タイプ2 | C1: 商品名 | D1: 計上月 | E1: 合計金額 | F1: N
A2: まとめ継続 | B2: 全体売上 | C2: 3ヶ月会員（ライト・クレカ自動更新） | D2: 46054 | E2: 0 | F2: 1
A3: まとめ継続 | B3: 全体売上 | C3: 3ヶ月会員（ライト・クレカ自動更新） | D3: 46082 | E3: 39600 | F3: 2
A4: まとめ継続 | B4: 全体売上 | C4: 3ヶ月会員（ライト・クレカ自動更新） | D4: 46113 | E4: 1762200 | F4: 3
A5: まとめ継続 | B5: 全体売上 | C5: 3ヶ月会員（ライト・クレカ自動更新） | D5: 46143 | E5: 2217600 | F5: 4
A6: まとめ継続 | B6: 全体売上 | C6: 3ヶ月会員（ライト・クレカ自動更新） | D6: 46174 | E6: 2178000 | F6: 5
A7: まとめ継続 | B7: 全体売上 | C7: 3ヶ月会員（ライト・クレカ自動更新） | D7: 46204 | E7: 455400 | F7: 6
A8: まとめ継続 | B8: 全体売上 | C8: 3ヶ月会員（ライト・クレカ自動更新） | D8: 46235 | E8: 0 | F8: 7
A9: まとめ継続 | B9: 全体売上 | C9: 3ヶ月会員（ライト・クレカ自動更新） | D9: 46266 | E9: 0 | F9: 8
A10: まとめ継続 | B10: 全体売上 | C10: 3ヶ月会員（ライト・クレカ自動更新） | D10: 46296 | E10: 0 | F10: 9
A11: まとめ継続 | B11: 全体売上 | C11: 3ヶ月会員（ライト・クレカ自動更新） | D11: 46327 | E11: 0 | F11: 10
A12: まとめ継続 | B12: 全体売上 | C12: 3ヶ月会員（ライト・クレカ自動更新） | D12: 46357 | E12: 0 | F12: 11
A13: まとめ継続 | B13: 全体売上 | C13: 3ヶ月会員（ライト・クレカ自動更新） | D13: 46388 | E13: 0 | F13: 12
... A265: まとめ継続 | B265: 自社分 | C265: 銀振会員（更新要ｶｸﾆﾝ）Apex年間 | D265: 46692 | E265: 0 | F265: 264

Sheet Sheet11 (12月)
A1: タイプ1 | B1: タイプ2 | C1: 商品名 | D1: 計上月 | E1: 合計金額 | F1: N
A2: まとめ継続 | B2: 全体売上 | C2: 3ヶ月会員（ライト・クレカ自動更新） | D2: 46023 | E2: 0 | F2: 1
A3: まとめ継続 | B3: 全体売上 | C3: 3ヶ月会員（ライト・クレカ自動更新） | D3: 46054 | E3: 336600 | F3: 2
A4: まとめ継続 | B4: 全体売上 | C4: 3ヶ月会員（ライト・クレカ自動更新） | D4: 46082 | E4: 376200 | F4: 3
A5: まとめ継続 | B5: 全体売上 | C5: 3ヶ月会員（ライト・クレカ自動更新） | D5: 46113 | E5: 2118600 | F5: 4
A6: まとめ継続 | B6: 全体売上 | C6: 3ヶ月会員（ライト・クレカ自動更新） | D6: 46143 | E6: 1782000 | F6: 5
A7: まとめ継続 | B7: 全体売上 | C7: 3ヶ月会員（ライト・クレカ自動更新） | D7: 46174 | E7: 1742400 | F7: 6
A8: まとめ継続 | B8: 全体売上 | C8: 3ヶ月会員（ライト・クレカ自動更新） | D8: 46204 | E8: 0 | F8: 7
A9: まとめ継続 | B9: 全体売上 | C9: 3ヶ月会員（ライト・クレカ自動更新） | D9: 46235 | E9: 0 | F9: 8
A10: まとめ継続 | B10: 全体売上 | C10: 3ヶ月会員（ライト・クレカ自動更新） | D10: 46266 | E10: 0 | F10: 9
A11: まとめ継続 | B11: 全体売上 | C11: 3ヶ月会員（ライト・クレカ自動更新） | D11: 46296 | E11: 0 | F11: 10
A12: まとめ継続 | B12: 全体売上 | C12: 3ヶ月会員（ライト・クレカ自動更新） | D12: 46327 | E12: 0 | F12: 11
A13: まとめ継続 | B13: 全体売上 | C13: 3ヶ月会員（ライト・クレカ自動更新） | D13: 46357 | E13: 0 | F13: 12
... A265: まとめ継続 | B265: 自社分 | C265: 銀振会員（更新要ｶｸﾆﾝ）Apex年間 | D265: 46661 | E265: 4245.75 | F265: 264

Sheet Sheet11 (11月)
A1: タイプ1 | B1: タイプ2 | C1: 商品名 | D1: 計上月 | E1: 合計金額 | F1: N
A2: まとめ継続 | B2: 全体売上 | C2: 3ヶ月会員（ライト・クレカ自動更新） | D2: 45992 | E2: 0 | F2: 1
A3: まとめ継続 | B3: 全体売上 | C3: 3ヶ月会員（ライト・クレカ自動更新） | D3: 46023 | E3: 930600 | F3: 2
A4: まとめ継続 | B4: 全体売上 | C4: 3ヶ月会員（ライト・クレカ自動更新） | D4: 46054 | E4: 1267200 | F4: 3
A5: まとめ継続 | B5: 全体売上 | C5: 3ヶ月会員（ライト・クレカ自動更新） | D5: 46082 | E5: 1306800 | F5: 4
A6: まとめ継続 | B6: 全体売上 | C6: 3ヶ月会員（ライト・クレカ自動更新） | D6: 46113 | E6: 732600 | F6: 5
A7: まとめ継続 | B7: 全体売上 | C7: 3ヶ月会員（ライト・クレカ自動更新） | D7: 46143 | E7: 396000 | F7: 6
A8: まとめ継続 | B8: 全体売上 | C8: 3ヶ月会員（ライト・クレカ自動更新） | D8: 46174 | E8: 356400 | F8: 7
A9: まとめ継続 | B9: 全体売上 | C9: 3ヶ月会員（ライト・クレカ自動更新） | D9: 46204 | E9: 0 | F9: 8
A10: まとめ継続 | B10: 全体売上 | C10: 3ヶ月会員（ライト・クレカ自動更新） | D10: 46235 | E10: 0 | F10: 9
A11: まとめ継続 | B11: 全体売上 | C11: 3ヶ月会員（ライト・クレカ自動更新） | D11: 46266 | E11: 0 | F11: 10
A12: まとめ継続 | B12: 全体売上 | C12: 3ヶ月会員（ライト・クレカ自動更新） | D12: 46296 | E12: 0 | F12: 11
A13: まとめ継続 | B13: 全体売上 | C13: 3ヶ月会員（ライト・クレカ自動更新） | D13: 46327 | E13: 0 | F13: 12
... A265: まとめ継続 | B265: 自社分 | C265: 銀振会員（更新要ｶｸﾆﾝ）Apex年間 | D265: 46631 | E265: 4245 | F265: 264

Sheet Sheet11 (10月)
A1: タイプ1 | B1: タイプ2 | C1: 商品名 | D1: 計上月 | E1: 合計金額 | F1: N
A2: まとめ継続 | B2: 全体売上 | C2: 3ヶ月会員（ライト・クレカ自動更新） | D2: 45962 | E2: 0 | F2: 1
A3: まとめ継続 | B3: 全体売上 | C3: 3ヶ月会員（ライト・クレカ自動更新） | D3: 45992 | E3: 39600 | F3: 2
A4: まとめ継続 | B4: 全体売上 | C4: 3ヶ月会員（ライト・クレカ自動更新） | D4: 46023 | E4: 990000 | F4: 3
A5: まとめ継続 | B5: 全体売上 | C5: 3ヶ月会員（ライト・クレカ自動更新） | D5: 46054 | E5: 1326600 | F5: 4
A6: まとめ継続 | B6: 全体売上 | C6: 3ヶ月会員（ライト・クレカ自動更新） | D6: 46082 | E6: 1306800 | F6: 5
A7: まとめ継続 | B7: 全体売上 | C7: 3ヶ月会員（ライト・クレカ自動更新） | D7: 46113 | E7: 356400 | F7: 6
A8: まとめ継続 | B8: 全体売上 | C8: 3ヶ月会員（ライト・クレカ自動更新） | D8: 46143 | E8: 19800 | F8: 7
A9: まとめ継続 | B9: 全体売上 | C9: 3ヶ月会員（ライト・クレカ自動更新） | D9: 46174 | E9: 0 | F9: 8
A10: まとめ継続 | B10: 全体売上 | C10: 3ヶ月会員（ライト・クレカ自動更新） | D10: 46204 | E10: 0 | F10: 9
A11: まとめ継続 | B11: 全体売上 | C11: 3ヶ月会員（ライト・クレカ自動更新） | D11: 46235 | E11: 0 | F11: 10
A12: まとめ継続 | B12: 全体売上 | C12: 3ヶ月会員（ライト・クレカ自動更新） | D12: 46266 | E12: 0 | F12: 11
A13: まとめ継続 | B13: 全体売上 | C13: 3ヶ月会員（ライト・クレカ自動更新） | D13: 46296 | E13: 0 | F13: 12
... A265: まとめ継続 | B265: 自社分 | C265: 銀振会員（更新要ｶｸﾆﾝ）Apex年間 | D265: 46600 | E265: 16983 | F265: 264

Sheet Sheet11 (9月)
A1: タイプ1 | B1: タイプ2 | C1: 商品名 | D1: 計上月 | E1: 合計金額 | F1: N
A2: まとめ継続 | B2: 全体売上 | C2: 3ヶ月会員（ライト・クレカ自動更新） | D2: 45931 | E2: 0 | F2: 1
A3: まとめ継続 | B3: 全体売上 | C3: 6ヶ月会員（ライト・クレカ自動更新） | D3: 45931 | E3: 0 | F3: 23
A4: まとめ継続 | B4: 全体売上 | C4: Apex年間会員（自動更新） | D4: 45931 | E4: 0 | F4: 45
A5: まとめ継続 | B5: 全体売上 | C5: 銀振会員（更新要ｶｸﾆﾝ）3ヶ月 | D5: 45931 | E5: 0 | F5: 68
A6: まとめ継続 | B6: 全体売上 | C6: 銀振会員（更新要ｶｸﾆﾝ）6ヶ月 | D6: 45931 | E6: 0 | F6: 90
A7: まとめ継続 | B7: 全体売上 | C7: 銀振会員（更新要ｶｸﾆﾝ）Apex年間 | D7: 45931 | E7: 0 | F7: 112
A8: まとめ継続 | B8: 自社分 | C8: 3ヶ月会員（ライト・クレカ自動更新） | D8: 45931 | E8: 0 | F8: 135
A9: まとめ継続 | B9: 自社分 | C9: 6ヶ月会員（ライト・クレカ自動更新） | D9: 45931 | E9: 0 | F9: 157
A10: まとめ継続 | B10: 自社分 | C10: Apex年間会員（自動更新） | D10: 45931 | E10: 0 | F10: 179
A11: まとめ継続 | B11: 自社分 | C11: 銀振会員（更新要ｶｸﾆﾝ）3ヶ月 | D11: 45931 | E11: 0 | F11: 202
A12: まとめ継続 | B12: 自社分 | C12: 銀振会員（更新要ｶｸﾆﾝ）6ヶ月 | D12: 45931 | E12: 0 | F12: 224
A13: まとめ継続 | B13: 自社分 | C13: 銀振会員（更新要ｶｸﾆﾝ）Apex年間 | D13: 45931 | E13: 0 | F13: 246
... A269: まとめ継続 | B269: 自社分 | C269: 銀振会員（更新要ｶｸﾆﾝ）Apex年間 | D269: 46600 | E269: 12737 | F269: 268

Sheet keisan
A1: タイプ1 | B1: タイプ2 | C1: 商品名 | D1: 計上月 | E1: 合計金額 | F1: N
A2: まとめ継続 | B2: 全体売上 | C2: 3ヶ月会員（ライト・クレカ自動更新） | D2: 45931 | E2: 0 | F2: 1
A3: まとめ継続 | B3: 全体売上 | C3: 3ヶ月会員（ライト・クレカ自動更新） | D3: 45962 | E3: 297000 | F3: 2
A4: まとめ継続 | B4: 全体売上 | C4: 3ヶ月会員（ライト・クレカ自動更新） | D4: 45992 | E4: 336600 | F4: 3
A5: まとめ継続 | B5: 全体売上 | C5: 3ヶ月会員（ライト・クレカ自動更新） | D5: 46023 | E5: 1306800 | F5: 4
A6: まとめ継続 | B6: 全体売上 | C6: 3ヶ月会員（ライト・クレカ自動更新） | D6: 46054 | E6: 1049400 | F6: 5
A7: まとめ継続 | B7: 全体売上 | C7: 3ヶ月会員（ライト・クレカ自動更新） | D7: 46082 | E7: 1009800 | F7: 6
A8: まとめ継続 | B8: 全体売上 | C8: 3ヶ月会員（ライト・クレカ自動更新） | D8: 46113 | E8: 39600 | F8: 7
A9: まとめ継続 | B9: 全体売上 | C9: 3ヶ月会員（ライト・クレカ自動更新） | D9: 46143 | E9: 0 | F9: 8
A10: まとめ継続 | B10: 全体売上 | C10: 3ヶ月会員（ライト・クレカ自動更新） | D10: 46174 | E10: 0 | F10: 9
A11: まとめ継続 | B11: 全体売上 | C11: 3ヶ月会員（ライト・クレカ自動更新） | D11: 46204 | E11: 0 | F11: 10
A12: まとめ継続 | B12: 全体売上 | C12: 3ヶ月会員（ライト・クレカ自動更新） | D12: 46235 | E12: 0 | F12: 11
A13: まとめ継続 | B13: 全体売上 | C13: 3ヶ月会員（ライト・クレカ自動更新） | D13: 46266 | E13: 0 | F13: 12
... A269: まとめ継続 | B269: 自社分 | C269: 銀振会員（更新要ｶｸﾆﾝ）Apex年間 | D269: 46600 | E269: 12737 | F269: 268

Sheet Sheet11 (8月)
A1: タイプ1 | B1: タイプ2 | C1: 商品名 | D1: 計上月 | E1: 合計金額 | F1: N
A2: まとめ継続 | B2: 全体売上 | C2: 3ヶ月会員（ライト・クレカ自動更新） | D2: 45901 | E2: 0 | F2: 1
A3: まとめ継続 | B3: 全体売上 | C3: 6ヶ月会員（ライト・クレカ自動更新） | D3: 45901 | E3: 0 | F3: 24
A4: まとめ継続 | B4: 全体売上 | C4: Apex年間会員（自動更新） | D4: 45901 | E4: 0 | F4: 47
A5: まとめ継続 | B5: 全体売上 | C5: 銀振会員（更新要ｶｸﾆﾝ）3ヶ月 | D5: 45901 | E5: 0 | F5: 71
A6: まとめ継続 | B6: 全体売上 | C6: 銀振会員（更新要ｶｸﾆﾝ）6ヶ月 | D6: 45901 | E6: 0 | F6: 94
A7: まとめ継続 | B7: 全体売上 | C7: 銀振会員（更新要ｶｸﾆﾝ）Apex年間 | D7: 45901 | E7: 0 | F7: 117
A8: まとめ継続 | B8: 自社分 | C8: 3ヶ月会員（ライト・クレカ自動更新） | D8: 45901 | E8: 0 | F8: 141
A9: まとめ継続 | B9: 自社分 | C9: 6ヶ月会員（ライト・クレカ自動更新） | D9: 45901 | E9: 0 | F9: 164
A10: まとめ継続 | B10: 自社分 | C10: Apex年間会員（自動更新） | D10: 45901 | E10: 0 | F10: 187
A11: まとめ継続 | B11: 自社分 | C11: 銀振会員（更新要ｶｸﾆﾝ）3ヶ月 | D11: 45901 | E11: 0 | F11: 211
A12: まとめ継続 | B12: 自社分 | C12: 銀振会員（更新要ｶｸﾆﾝ）6ヶ月 | D12: 45901 | E12: 0 | F12: 234
A13: まとめ継続 | B13: 自社分 | C13: 銀振会員（更新要ｶｸﾆﾝ）Apex年間 | D13: 45901 | E13: 0 | F13: 257
... A281: まとめ継続 | B281: 自社分 | C281: 銀振会員（更新要ｶｸﾆﾝ）Apex年間 | D281: 46600 | E281: 12737.25 | F281: 280

Sheet Sheet11 (7月)
A1: タイプ1 | B1: タイプ2 | C1: 商品名 | D1: 計上月 | E1: 合計金額 | F1: N
A2: まとめ継続 | B2: 全体売上 | C2: 3ヶ月会員（ライト・クレカ自動更新） | D2: 45870 | E2: 0 | F2: 1
A3: まとめ継続 | B3: 全体売上 | C3: 3ヶ月会員（ライト・クレカ自動更新） | D3: 45901 | E3: 39600 | F3: 2
A4: まとめ継続 | B4: 全体売上 | C4: 3ヶ月会員（ライト・クレカ自動更新） | D4: 45931 | E4: 1148400 | F4: 3
A5: まとめ継続 | B5: 全体売上 | C5: 3ヶ月会員（ライト・クレカ自動更新） | D5: 45962 | E5: 1445400 | F5: 4
A6: まとめ継続 | B6: 全体売上 | C6: 3ヶ月会員（ライト・クレカ自動更新） | D6: 45992 | E6: 1405800 | F6: 5
A7: まとめ継続 | B7: 全体売上 | C7: 3ヶ月会員（ライト・クレカ自動更新） | D7: 46023 | E7: 297000 | F7: 6
A8: まとめ継続 | B8: 全体売上 | C8: 3ヶ月会員（ライト・クレカ自動更新） | D8: 46054 | E8: 0 | F8: 7
A9: まとめ継続 | B9: 全体売上 | C9: 3ヶ月会員（ライト・クレカ自動更新） | D9: 46082 | E9: 0 | F9: 8
A10: まとめ継続 | B10: 全体売上 | C10: 3ヶ月会員（ライト・クレカ自動更新） | D10: 46113 | E10: 0 | F10: 9
A11: まとめ継続 | B11: 全体売上 | C11: 3ヶ月会員（ライト・クレカ自動更新） | D11: 46143 | E11: 0 | F11: 10
A12: まとめ継続 | B12: 全体売上 | C12: 3ヶ月会員（ライト・クレカ自動更新） | D12: 46174 | E12: 0 | F12: 11
A13: まとめ継続 | B13: 全体売上 | C13: 3ヶ月会員（ライト・クレカ自動更新） | D13: 46204 | E13: 0 | F13: 12
... A289: まとめ継続 | B289: 自社分 | C289: 銀振会員（更新要ｶｸﾆﾝ）Apex年間 | D289: 46569 | E289: 0 | F289: 288

Sheet Sheet11 (6月)
A1: タイプ1 | B1: タイプ2 | C1: 商品名 | D1: 計上月 | E1: 合計金額 | F1: N | H1: 0.45
A2: まとめ継続 | B2: 全体売上 | C2: 3ヶ月会員（ライト・クレカ自動更新） | D2: 45839 | F2: 1
A3: まとめ継続 | B3: 全体売上 | C3: 3ヶ月会員（ライト・クレカ自動更新） | D3: 45870 | E3: 297000 | F3: 2
A4: まとめ継続 | B4: 全体売上 | C4: 3ヶ月会員（ライト・クレカ自動更新） | D4: 45901 | E4: 336600 | F4: 3
A5: まとめ継続 | B5: 全体売上 | C5: 3ヶ月会員（ライト・クレカ自動更新） | D5: 45931 | E5: 1445400 | F5: 4
A6: まとめ継続 | B6: 全体売上 | C6: 3ヶ月会員（ライト・クレカ自動更新） | D6: 45962 | E6: 1168200 | F6: 5
A7: まとめ継続 | B7: 全体売上 | C7: 3ヶ月会員（ライト・クレカ自動更新） | D7: 45992 | E7: 1128600 | F7: 6
A8: まとめ継続 | B8: 全体売上 | C8: 3ヶ月会員（ライト・クレカ自動更新） | D8: 46023 | E8: 19800 | F8: 7
A9: まとめ継続 | B9: 全体売上 | C9: 3ヶ月会員（ライト・クレカ自動更新） | D9: 46054 | F9: 8
A10: まとめ継続 | B10: 全体売上 | C10: 3ヶ月会員（ライト・クレカ自動更新） | D10: 46082 | F10: 9
A11: まとめ継続 | B11: 全体売上 | C11: 3ヶ月会員（ライト・クレカ自動更新） | D11: 46113 | F11: 10
A12: まとめ継続 | B12: 全体売上 | C12: 3ヶ月会員（ライト・クレカ自動更新） | D12: 46143 | F12: 11
A13: まとめ継続 | B13: 全体売上 | C13: 3ヶ月会員（ライト・クレカ自動更新） | D13: 46174 | F13: 12
A14: まとめ継続 | B14: 全体売上 | C14: 3ヶ月会員（ライト・クレカ自動更新） | D14: 46204 | F14: 13
A15: まとめ継続 | B15: 全体売上 | C15: 3ヶ月会員（ライト・クレカ自動更新） | D15: 46235 | F15: 14
A16: まとめ継続 | B16: 全体売上 | C16: 3ヶ月会員（ライト・クレカ自動更新） | D16: 46266 | F16: 15
A17: まとめ継続 | B17: 全体売上 | C17: 3ヶ月会員（ライト・クレカ自動更新） | D17: 46296 | F17: 16
A18: まとめ継続 | B18: 全体売上 | C18: 3ヶ月会員（ライト・クレカ自動更新） | D18: 46327 | F18: 17
A19: まとめ継続 | B19: 全体売上 | C19: 3ヶ月会員（ライト・クレカ自動更新） | D19: 46357 | F19: 18
A20: まとめ継続 | B20: 全体売上 | C20: 3ヶ月会員（ライト・クレカ自動更新） | D20: 46388 | F20: 19
... A27: まとめ継続 | B27: 全体売上 | C27: 6ヶ月会員（ライト・クレカ自動更新） | D27: 45839 | F27: 26
A28: まとめ継続 | B28: 全体売上 | C28: 6ヶ月会員（ライト・クレカ自動更新） | D28: 45870 | E28: 114300 | F28: 27
A29: まとめ継続 | B29: 全体売上 | C29: 6ヶ月会員（ライト・クレカ自動更新） | D29: 45901 | E29: 209550 | F29: 28
A30: まとめ継続 | B30: 全体売上 | C30: 6ヶ月会員（ライト・クレカ自動更新） | D30: 45931 | E30: 742950 | F30: 29
A31: まとめ継続 | B31: 全体売上 | C31: 6ヶ月会員（ライト・クレカ自動更新） | D31: 45962 | E31: 2705100 | F31: 30
A32: まとめ継続 | B32: 全体売上 | C32: 6ヶ月会員（ライト・クレカ自動更新） | D32: 45992 | E32: 2838450 | F32: 31
A33: まとめ継続 | B33: 全体売上 | C33: 6ヶ月会員（ライト・クレカ自動更新） | D33: 46023 | E33: 7867650 | F33: 32
A34: まとめ継続 | B34: 全体売上 | C34: 6ヶ月会員（ライト・クレカ自動更新） | D34: 46054 | E34: 7753350 | F34: 33
A35: まとめ継続 | B35: 全体売上 | C35: 6ヶ月会員（ライト・クレカ自動更新） | D35: 46082 | E35: 7658100 | F35: 34
A36: まとめ継続 | B36: 全体売上 | C36: 6ヶ月会員（ライト・クレカ自動更新） | D36: 46113 | E36: 7124700 | F36: 35
A37: まとめ継続 | B37: 全体売上 | C37: 6ヶ月会員（ライト・クレカ自動更新） | D37: 46143 | E37: 5162550 | F37: 36
A38: まとめ継続 | B38: 全体売上 | C38: 6ヶ月会員（ライト・クレカ自動更新） | D38: 46174 | E38: 5029200 | F38: 37
A39: まとめ継続 | B39: 全体売上 | C39: 6ヶ月会員（ライト・クレカ自動更新） | D39: 46204 | F39: 38
A40: まとめ継続 | B40: 全体売上 | C40: 6ヶ月会員（ライト・クレカ自動更新） | D40: 46235 | F40: 39
A41: まとめ継続 | B41: 全体売上 | C41: 6ヶ月会員（ライト・クレカ自動更新） | D41: 46266 | F41: 40
A42: まとめ継続 | B42: 全体売上 | C42: 6ヶ月会員（ライト・クレカ自動更新） | D42: 46296 | F42: 41
A43: まとめ継続 | B43: 全体売上 | C43: 6ヶ月会員（ライト・クレカ自動更新） | D43: 46327 | F43: 42
A44: まとめ継続 | B44: 全体売上 | C44: 6ヶ月会員（ライト・クレカ自動更新） | D44: 46357 | F44: 43
A45: まとめ継続 | B45: 全体売上 | C45: 6ヶ月会員（ライト・クレカ自動更新） | D45: 46388 | F45: 44
A46: まとめ継続 | B46: 全体売上 | C46: 6ヶ月会員（ライト・クレカ自動更新） | D46: 46419 | F46: 45
...

Sheet Sheet11 (5月)
A1: タイプ1 | B1: タイプ2 | C1: 商品名 | D1: 計上月 | E1: 合計金額 | F1: N | H1: 0.45
A2: まとめ継続 | B2: 全体売上 | C2: 3ヶ月会員（ライト・クレカ自動更新） | D2: 45809 | F2: 1
A3: まとめ継続 | B3: 全体売上 | C3: 3ヶ月会員（ライト・クレカ自動更新） | D3: 45839 | E3: 1108800 | F3: 2
A4: まとめ継続 | B4: 全体売上 | C4: 3ヶ月会員（ライト・クレカ自動更新） | D4: 45870 | E4: 1405800 | F4: 3
A5: まとめ継続 | B5: 全体売上 | C5: 3ヶ月会員（ライト・クレカ自動更新） | D5: 45901 | E5: 1445400 | F5: 4
A6: まとめ継続 | B6: 全体売上 | C6: 3ヶ月会員（ライト・クレカ自動更新） | D6: 45931 | E6: 356400 | F6: 5
A7: まとめ継続 | B7: 全体売上 | C7: 3ヶ月会員（ライト・クレカ自動更新） | D7: 45962 | E7: 59400 | F7: 6
A8: まとめ継続 | B8: 全体売上 | C8: 3ヶ月会員（ライト・クレカ自動更新） | D8: 45992 | E8: 19800 | F8: 7
A9: まとめ継続 | B9: 全体売上 | C9: 3ヶ月会員（ライト・クレカ自動更新） | D9: 46023 | F9: 8
A10: まとめ継続 | B10: 全体売上 | C10: 3ヶ月会員（ライト・クレカ自動更新） | D10: 46054 | F10: 9
A11: まとめ継続 | B11: 全体売上 | C11: 3ヶ月会員（ライト・クレカ自動更新） | D11: 46082 | F11: 10
A12: まとめ継続 | B12: 全体売上 | C12: 3ヶ月会員（ライト・クレカ自動更新） | D12: 46113 | F12: 11
A13: まとめ継続 | B13: 全体売上 | C13: 3ヶ月会員（ライト・クレカ自動更新） | D13: 46143 | F13: 12
A14: まとめ継続 | B14: 全体売上 | C14: 3ヶ月会員（ライト・クレカ自動更新） | D14: 46174 | F14: 13
A15: まとめ継続 | B15: 全体売上 | C15: 3ヶ月会員（ライト・クレカ自動更新） | D15: 46204 | F15: 14
A16: まとめ継続 | B16: 全体売上 | C16: 3ヶ月会員（ライト・クレカ自動更新） | D16: 46235 | F16: 15
A17: まとめ継続 | B17: 全体売上 | C17: 3ヶ月会員（ライト・クレカ自動更新） | D17: 46266 | F17: 16
A18: まとめ継続 | B18: 全体売上 | C18: 3ヶ月会員（ライト・クレカ自動更新） | D18: 46296 | F18: 17
A19: まとめ継続 | B19: 全体売上 | C19: 3ヶ月会員（ライト・クレカ自動更新） | D19: 46327 | F19: 18
A20: まとめ継続 | B20: 全体売上 | C20: 3ヶ月会員（ライト・クレカ自動更新） | D20: 46357 | F20: 19
... A26: まとめ継続 | B26: 全体売上 | C26: 6ヶ月会員（ライト・クレカ自動更新） | D26: 45809 | F26: 25
A27: まとめ継続 | B27: 全体売上 | C27: 6ヶ月会員（ライト・クレカ自動更新） | D27: 45839 | E27: 5657850 | F27: 26
A28: まとめ継続 | B28: 全体売上 | C28: 6ヶ月会員（ライト・クレカ自動更新） | D28: 45870 | E28: 5772150 | F28: 27
A29: まとめ継続 | B29: 全体売上 | C29: 6ヶ月会員（ライト・クレカ自動更新） | D29: 45901 | E29: 5867400 | F29: 28
A30: まとめ継続 | B30: 全体売上 | C30: 6ヶ月会員（ライト・クレカ自動更新） | D30: 45931 | E30: 6400800 | F30: 29
A31: まとめ継続 | B31: 全体売上 | C31: 6ヶ月会員（ライト・クレカ自動更新） | D31: 45962 | E31: 8362950 | F31: 30
A32: まとめ継続 | B32: 全体売上 | C32: 6ヶ月会員（ライト・クレカ自動更新） | D32: 45992 | E32: 8496300 | F32: 31
A33: まとめ継続 | B33: 全体売上 | C33: 6ヶ月会員（ライト・クレカ自動更新） | D33: 46023 | E33: 2876550 | F33: 32
A34: まとめ継続 | B34: 全体売上 | C34: 6ヶ月会員（ライト・クレカ自動更新） | D34: 46054 | E34: 2762250 | F34: 33
A35: まとめ継続 | B35: 全体売上 | C35: 6ヶ月会員（ライト・クレカ自動更新） | D35: 46082 | E35: 2667000 | F35: 34
A36: まとめ継続 | B36: 全体売上 | C36: 6ヶ月会員（ライト・クレカ自動更新） | D36: 46113 | E36: 2133600 | F36: 35
A37: まとめ継続 | B37: 全体売上 | C37: 6ヶ月会員（ライト・クレカ自動更新） | D37: 46143 | E37: 171450 | F37: 36
A38: まとめ継続 | B38: 全体売上 | C38: 6ヶ月会員（ライト・クレカ自動更新） | D38: 46174 | E38: 38100 | F38: 37
A39: まとめ継続 | B39: 全体売上 | C39: 6ヶ月会員（ライト・クレカ自動更新） | D39: 46204 | F39: 38
A40: まとめ継続 | B40: 全体売上 | C40: 6ヶ月会員（ライト・クレカ自動更新） | D40: 46235 | F40: 39
A41: まとめ継続 | B41: 全体売上 | C41: 6ヶ月会員（ライト・クレカ自動更新） | D41: 46266 | F41: 40
A42: まとめ継続 | B42: 全体売上 | C42: 6ヶ月会員（ライト・クレカ自動更新） | D42: 46296 | F42: 41
A43: まとめ継続 | B43: 全体売上 | C43: 6ヶ月会員（ライト・クレカ自動更新） | D43: 46327 | F43: 42
A44: まとめ継続 | B44: 全体売上 | C44: 6ヶ月会員（ライト・クレカ自動更新） | D44: 46357 | F44: 43
A45: まとめ継続 | B45: 全体売上 | C45: 6ヶ月会員（ライト・クレカ自動更新） | D45: 46388 | F45: 44
...

Sheet Sheet11 (4月)
A1: タイプ1 | B1: タイプ2 | C1: 商品名 | D1: 計上月 | E1: 合計金額 | F1: N
A2: まとめ継続 | B2: 全体売上 | C2: 3ヶ月会員（ライト・クレカ自動更新） | D2: 45778 | F2: 1
A3: まとめ継続 | B3: 全体売上 | C3: 3ヶ月会員（ライト・クレカ自動更新） | D3: 45809 | E3: 39600 | F3: 2
A4: まとめ継続 | B4: 全体売上 | C4: 3ヶ月会員（ライト・クレカ自動更新） | D4: 45839 | E4: 1207800 | F4: 3
A5: まとめ継続 | B5: 全体売上 | C5: 3ヶ月会員（ライト・クレカ自動更新） | D5: 45870 | E5: 1485000 | F5: 4
A6: まとめ継続 | B6: 全体売上 | C6: 3ヶ月会員（ライト・クレカ自動更新） | D6: 45901 | E6: 1445400 | F6: 5
A7: まとめ継続 | B7: 全体売上 | C7: 3ヶ月会員（ライト・クレカ自動更新） | D7: 45931 | E7: 277200 | F7: 6
A8: まとめ継続 | B8: 全体売上 | C8: 3ヶ月会員（ライト・クレカ自動更新） | D8: 45962 | F8: 7
A9: まとめ継続 | B9: 全体売上 | C9: 3ヶ月会員（ライト・クレカ自動更新） | D9: 45992 | F9: 8
A10: まとめ継続 | B10: 全体売上 | C10: 3ヶ月会員（ライト・クレカ自動更新） | D10: 46023 | F10: 9
A11: まとめ継続 | B11: 全体売上 | C11: 3ヶ月会員（ライト・クレカ自動更新） | D11: 46054 | F11: 10
A12: まとめ継続 | B12: 全体売上 | C12: 3ヶ月会員（ライト・クレカ自動更新） | D12: 46082 | F12: 11
A13: まとめ継続 | B13: 全体売上 | C13: 3ヶ月会員（ライト・クレカ自動更新） | D13: 46113 | F13: 12
A14: まとめ継続 | B14: 全体売上 | C14: 3ヶ月会員（ライト・クレカ自動更新） | D14: 46143 | F14: 13
A15: まとめ継続 | B15: 全体売上 | C15: 3ヶ月会員（ライト・クレカ自動更新） | D15: 46174 | F15: 14
A16: まとめ継続 | B16: 全体売上 | C16: 3ヶ月会員（ライト・クレカ自動更新） | D16: 46204 | F16: 15
A17: まとめ継続 | B17: 全体売上 | C17: 3ヶ月会員（ライト・クレカ自動更新） | D17: 46235 | F17: 16
A18: まとめ継続 | B18: 全体売上 | C18: 3ヶ月会員（ライト・クレカ自動更新） | D18: 46266 | F18: 17
A19: まとめ継続 | B19: 全体売上 | C19: 3ヶ月会員（ライト・クレカ自動更新） | D19: 46296 | F19: 18
... A25: まとめ継続 | B25: 全体売上 | C25: 6ヶ月会員（ライト・クレカ自動更新） | D25: 45778 | F25: 24
A26: まとめ継続 | B26: 全体売上 | C26: 6ヶ月会員（ライト・クレカ自動更新） | D26: 45809 | E26: 171450 | F26: 25
A27: まとめ継続 | B27: 全体売上 | C27: 6ヶ月会員（ライト・クレカ自動更新） | D27: 45839 | E27: 6248400 | F27: 26
A28: まとめ継続 | B28: 全体売上 | C28: 6ヶ月会員（ライト・クレカ自動更新） | D28: 45870 | E28: 6362700 | F28: 27
A29: まとめ継続 | B29: 全体売上 | C29: 6ヶ月会員（ライト・クレカ自動更新） | D29: 45901 | E29: 6457950 | F29: 28
A30: まとめ継続 | B30: 全体売上 | C30: 6ヶ月会員（ライト・クレカ自動更新） | D30: 45931 | E30: 6991350 | F30: 29
A31: まとめ継続 | B31: 全体売上 | C31: 6ヶ月会員（ライト・クレカ自動更新） | D31: 45962 | E31: 8953500 | F31: 30
A32: まとめ継続 | B32: 全体売上 | C32: 6ヶ月会員（ライト・クレカ自動更新） | D32: 45992 | E32: 8801100 | F32: 31
A33: まとめ継続 | B33: 全体売上 | C33: 6ヶ月会員（ライト・クレカ自動更新） | D33: 46023 | E33: 2724150 | F33: 32
A34: まとめ継続 | B34: 全体売上 | C34: 6ヶ月会員（ライト・クレカ自動更新） | D34: 46054 | E34: 2609850 | F34: 33
A35: まとめ継続 | B35: 全体売上 | C35: 6ヶ月会員（ライト・クレカ自動更新） | D35: 46082 | E35: 2514600 | F35: 34
A36: まとめ継続 | B36: 全体売上 | C36: 6ヶ月会員（ライト・クレカ自動更新） | D36: 46113 | E36: 1981200 | F36: 35
A37: まとめ継続 | B37: 全体売上 | C37: 6ヶ月会員（ライト・クレカ自動更新） | D37: 46143 | E37: 19050 | F37: 36
A38: まとめ継続 | B38: 全体売上 | C38: 6ヶ月会員（ライト・クレカ自動更新） | D38: 46174 | F38: 37
A39: まとめ継続 | B39: 全体売上 | C39: 6ヶ月会員（ライト・クレカ自動更新） | D39: 46204 | F39: 38
A40: まとめ継続 | B40: 全体売上 | C40: 6ヶ月会員（ライト・クレカ自動更新） | D40: 46235 | F40: 39
A41: まとめ継続 | B41: 全体売上 | C41: 6ヶ月会員（ライト・クレカ自動更新） | D41: 46266 | F41: 40
A42: まとめ継続 | B42: 全体売上 | C42: 6ヶ月会員（ライト・クレカ自動更新） | D42: 46296 | F42: 41
A43: まとめ継続 | B43: 全体売上 | C43: 6ヶ月会員（ライト・クレカ自動更新） | D43: 46327 | F43: 42
A44: まとめ継続 | B44: 全体売上 | C44: 6ヶ月会員（ライト・クレカ自動更新） | D44: 46357 | F44: 43
A45: まとめ継続 | B45: 全体売上 | C45: 6ヶ月会員（ライト・クレカ自動更新） | D45: 46388 | F45: 44
...

Sheet Sheet11(3月)
A1: タイプ1 | B1: タイプ2 | C1: 商品名 | D1: 計上月 | E1: 合計金額 | F1: N
A2: まとめ継続 | B2: 全体売上 | C2: 3ヶ月会員（ライト・クレカ自動更新） | D2: 45778 | E2: 415800 | F2: 1
A3: まとめ継続 | B3: 全体売上 | C3: 6ヶ月会員（ライト・クレカ自動更新） | D3: 45778 | E3: 2381250 | F3: 2
A4: まとめ継続 | B4: 全体売上 | C4: Apex年間会員（自動更新） | D4: 45778 | E4: 56610 | F4: 3
A5: まとめ継続 | B5: 全体売上 | C5: 銀振会員（更新要ｶｸﾆﾝ）3ヶ月 | D5: 45778 | E5: 0 | F5: 4
A6: まとめ継続 | B6: 全体売上 | C6: 銀振会員（更新要ｶｸﾆﾝ）6ヶ月 | D6: 45778 | E6: 76200 | F6: 5
A7: まとめ継続 | B7: 全体売上 | C7: 銀振会員（更新要ｶｸﾆﾝ）Apex年間 | D7: 45778 | E7: 0 | F7: 6
A8: まとめ継続 | B8: 全体売上 | C8: 3ヶ月会員（ライト・クレカ自動更新） | D8: 45809 | E8: 455400 | F8: 7
A9: まとめ継続 | B9: 全体売上 | C9: 6ヶ月会員（ライト・クレカ自動更新） | D9: 45809 | E9: 2552700 | F9: 8
A10: まとめ継続 | B10: 全体売上 | C10: Apex年間会員（自動更新） | D10: 45809 | E10: 84915 | F10: 9
A11: まとめ継続 | B11: 全体売上 | C11: 銀振会員（更新要ｶｸﾆﾝ）3ヶ月 | D11: 45809 | E11: 0 | F11: 10
A12: まとめ継続 | B12: 全体売上 | C12: 銀振会員（更新要ｶｸﾆﾝ）6ヶ月 | D12: 45809 | E12: 76200 | F12: 11
A13: まとめ継続 | B13: 全体売上 | C13: 銀振会員（更新要ｶｸﾆﾝ）Apex年間 | D13: 45809 | E13: 0 | F13: 12
... A169: まとめ継続 | B169: 自社分 | C169: 銀振会員（更新要ｶｸﾆﾝ）Apex年間 | D169: 46174 | E169: 12737 | F169: 168

Sheet Sheet11(2月)
A1: タイプ1 | B1: タイプ2 | C1: 商品名 | D1: 計上月 | E1: 合計金額
A2: まとめ継続 | B2: 全体売上 | C2: 6ヶ月会員（ライト・クレカ自動更新） | D2: 2025年03月 | E2: 38100
A3: まとめ継続 | B3: 自社分 | C3: 6ヶ月会員（ライト・クレカ自動更新） | D3: 2025年03月 | E3: 17145
A4: まとめ継続 | B4: 全体売上 | C4: 3ヶ月会員（ライト・クレカ自動更新） | D4: 2025年04月 | E4: 1544400
A5: まとめ継続 | B5: 全体売上 | C5: 6ヶ月会員（ライト・クレカ自動更新） | D5: 2025年04月 | E5: 533400
A6: まとめ継続 | B6: 全体売上 | C6: 銀振会員（更新要ｶｸﾆﾝ）3ヶ月 | D6: 2025年04月 | E6: 178200
A7: まとめ継続 | B7: 自社分 | C7: 3ヶ月会員（ライト・クレカ自動更新） | D7: 2025年04月 | E7: 694980
A8: まとめ継続 | B8: 自社分 | C8: 6ヶ月会員（ライト・クレカ自動更新） | D8: 2025年04月 | E8: 240030
A9: まとめ継続 | B9: 自社分 | C9: 銀振会員（更新要ｶｸﾆﾝ）3ヶ月 | D9: 2025年04月 | E9: 80190
A10: まとめ継続 | B10: 全体売上 | C10: 3ヶ月会員（ライト・クレカ自動更新） | D10: 2025年05月 | E10: 2019600
A11: まとめ継続 | B11: 全体売上 | C11: 6ヶ月会員（ライト・クレカ自動更新） | D11: 2025年05月 | E11: 2990850
A12: まとめ継続 | B12: 全体売上 | C12: Apex年間会員（自動更新） | D12: 2025年05月 | E12: 56610
A13: まとめ継続 | B13: 全体売上 | C13: 銀振会員（更新要ｶｸﾆﾝ）3ヶ月 | D13: 2025年05月 | E13: 198000
... A85: まとめ継続 | B85: 自社分 | C85: 銀振会員（更新要ｶｸﾆﾝ）Apex年間 | D85: 2026年01月 | E85: 12737

Sheet Sheet11 (並べ替えの都合上の削除前)
A1: タイプ1 | B1: タイプ2 | C1: 商品名 | D1: 計上月 | E1: 合計金額
A2: まとめ継続 | B2: 全体売上 | C2: 6ヶ月会員（ライト・クレカ自動更新） | D2: 2025年03月 | E2: 38100 | N2: 3ヶ月会員（ライト・クレカ自動更新） | O2: 6ヶ月会員（ライト・クレカ自動更新） | P2: Apex年間会員（自動更新） | Q2: 銀振会員（更新要ｶｸﾆﾝ）3ヶ月 | R2: 銀振会員（更新要ｶｸﾆﾝ）6ヶ月 | S2: 銀振会員（更新要ｶｸﾆﾝ）Apex年間 | T2: 総計 | U2: 0.45
A3: まとめ継続 | B3: 自社分 | C3: 6ヶ月会員（ライト・クレカ自動更新） | D3: 2025年03月 | E3: 17145 | M3: 2025年3月 | O3: 38100 | T3: 38100
A4: まとめ継続 | B4: 全体売上 | C4: 3ヶ月会員（ライト・クレカ自動更新） | D4: 2025年04月 | E4: 1544400 | M4: 2025年4月 | N4: 1544400 | O4: 533400 | Q4: 178200 | T4: 2256000
A5: まとめ継続 | B5: 全体売上 | C5: 6ヶ月会員（ライト・クレカ自動更新） | D5: 2025年04月 | E5: 533400 | M5: 2025年5月 | N5: 2019600 | O5: 2990850 | P5: 56610 | Q5: 198000 | R5: 76200 | T5: 5341260
A6: まとめ継続 | B6: 全体売上 | C6: 銀振会員（更新要ｶｸﾆﾝ）3ヶ月 | D6: 2025年04月 | E6: 178200 | M6: 2025年6月 | N6: 2059200 | O6: 3162300 | P6: 84915 | Q6: 198000 | R6: 76200 | T6: 5580615
A7: まとめ継続 | B7: 自社分 | C7: 3ヶ月会員（ライト・クレカ自動更新） | D7: 2025年04月 | E7: 694980 | M7: 2025年7月 | N7: 514800 | O7: 9315450 | P7: 84915 | Q7: 19800 | R7: 495300 | T7: 10430265
A8: まとめ継続 | B8: 自社分 | C8: 6ヶ月会員（ライト・クレカ自動更新） | D8: 2025年04月 | E8: 240030 | M8: 2025年8月 | N8: 39600 | O8: 9429750 | P8: 94350 | R8: 495300 | T8: 10059000
A9: まとめ継続 | B9: 自社分 | C9: 銀振会員（更新要ｶｸﾆﾝ）3ヶ月 | D9: 2025年04月 | E9: 80190 | M9: 2025年9月 | O9: 9486900 | P9: 245310 | R9: 495300 | S9: 28305 | T9: 10255815
A10: まとめ継続 | B10: 全体売上 | C10: 3ヶ月会員（ライト・クレカ自動更新） | D10: 2025年05月 | E10: 2019600 | M10: 2025年10月 | O10: 9010650 | P10: 245310 | R10: 495300 | S10: 28305 | T10: 9779565
A11: まとめ継続 | B11: 全体売上 | C11: 6ヶ月会員（ライト・クレカ自動更新） | D11: 2025年05月 | E11: 2990850 | M11: 2025年11月 | O11: 6553200 | P11: 245310 | R11: 419100 | S11: 28305 | T11: 7245915
A12: まとめ継続 | B12: 全体売上 | C12: Apex年間会員（自動更新） | D12: 2025年05月 | E12: 56610 | M12: 2025年12月 | O12: 6381750 | P12: 254745 | R12: 419100 | S12: 28305 | T12: 7083900
A13: まとめ継続 | B13: 全体売上 | C13: 銀振会員（更新要ｶｸﾆﾝ）3ヶ月 | D13: 2025年05月 | E13: 198000 | M13: 2026年1月 | O13: 228600 | P13: 254745 | S13: 28305 | T13: 511650
A14: まとめ継続 | B14: 全体売上 | C14: 銀振会員（更新要ｶｸﾆﾝ）6ヶ月 | D14: 2025年05月 | E14: 76200 | M14: 2026年2月 | O14: 114300 | P14: 254745 | S14: 28305 | T14: 397350
A15: まとめ継続 | B15: 自社分 | C15: 3ヶ月会員（ライト・クレカ自動更新） | D15: 2025年05月 | E15: 908820 | M15: 2026年3月 | O15: 19050 | P15: 349095 | S15: 28305 | T15: 396450
A16: まとめ継続 | B16: 自社分 | C16: 6ヶ月会員（ライト・クレカ自動更新） | D16: 2025年05月 | E16: 1345882 | M16: 2026年4月 | P16: 349095 | S16: 28305 | T16: 377400
A17: まとめ継続 | B17: 自社分 | C17: Apex年間会員（自動更新） | D17: 2025年05月 | E17: 25474 | M17: 2026年5月 | P17: 292485 | S17: 28305 | T17: 320790
A18: まとめ継続 | B18: 自社分 | C18: 銀振会員（更新要ｶｸﾆﾝ）3ヶ月 | D18: 2025年05月 | E18: 89100 | M18: 2026年6月 | P18: 264180 | S18: 28305 | T18: 292485
A19: まとめ継続 | B19: 自社分 | C19: 銀振会員（更新要ｶｸﾆﾝ）6ヶ月 | D19: 2025年05月 | E19: 34290 | M19: 2026年7月 | P19: 264180 | S19: 28305 | T19: 292485
A20: まとめ継続 | B20: 全体売上 | C20: 3ヶ月会員（ライト・クレカ自動更新） | D20: 2025年06月 | E20: 2059200 | M20: 2026年8月 | P20: 254745 | S20: 28305 | T20: 283050
A21: まとめ継続 | B21: 全体売上 | C21: 6ヶ月会員（ライト・クレカ自動更新） | D21: 2025年06月 | E21: 3162300 | M21: 2026年9月 | P21: 103785 | T21: 103785
A22: まとめ継続 | B22: 全体売上 | C22: Apex年間会員（自動更新） | D22: 2025年06月 | E22: 84915 | M22: 2026年10月 | P22: 103785 | T22: 103785
A23: まとめ継続 | B23: 全体売上 | C23: 銀振会員（更新要ｶｸﾆﾝ）3ヶ月 | D23: 2025年06月 | E23: 198000 | M23: 2026年11月 | P23: 103785 | T23: 103785
A24: まとめ継続 | B24: 全体売上 | C24: 銀振会員（更新要ｶｸﾆﾝ）6ヶ月 | D24: 2025年06月 | E24: 76200 | M24: 2026年12月 | P24: 94350 | T24: 94350
A25: まとめ継続 | B25: 自社分 | C25: 3ヶ月会員（ライト・クレカ自動更新） | D25: 2025年06月 | E25: 926640 | M25: 2027年1月 | P25: 94350 | T25: 94350
A26: まとめ継続 | B26: 自社分 | C26: 6ヶ月会員（ライト・クレカ自動更新） | D26: 2025年06月 | E26: 1423035 | M26: 2027年2月 | P26: 94350 | T26: 94350
A27: まとめ継続 | B27: 自社分 | C27: Apex年間会員（自動更新） | D27: 2025年06月 | E27: 38211 | M27: 2027年3月
A28: まとめ継続 | B28: 自社分 | C28: 銀振会員（更新要ｶｸﾆﾝ）3ヶ月 | D28: 2025年06月 | E28: 89100
A29: まとめ継続 | B29: 自社分 | C29: 銀振会員（更新要ｶｸﾆﾝ）6ヶ月 | D29: 2025年06月 | E29: 34290
A30: まとめ継続 | B30: 全体売上 | C30: 3ヶ月会員（ライト・クレカ自動更新） | D30: 2025年07月 | E30: 514800
A31: まとめ継続 | B31: 全体売上 | C31: 6ヶ月会員（ライト・クレカ自動更新） | D31: 2025年07月 | E31: 9315450
A32: まとめ継続 | B32: 全体売上 | C32: Apex年間会員（自動更新） | D32: 2025年07月 | E32: 84915
A33: まとめ継続 | B33: 全体売上 | C33: 銀振会員（更新要ｶｸﾆﾝ）3ヶ月 | D33: 2025年07月 | E33: 19800
A34: まとめ継続 | B34: 全体売上 | C34: 銀振会員（更新要ｶｸﾆﾝ）6ヶ月 | D34: 2025年07月 | E34: 495300
A35: まとめ継続 | B35: 自社分 | C35: 3ヶ月会員（ライト・クレカ自動更新） | D35: 2025年07月 | E35: 231660
A36: まとめ継続 | B36: 自社分 | C36: 6ヶ月会員（ライト・クレカ自動更新） | D36: 2025年07月 | E36: 4191952
A37: まとめ継続 | B37: 自社分 | C37: Apex年間会員（自動更新） | D37: 2025年07月 | E37: 38211
A38: まとめ継続 | B38: 自社分 | C38: 銀振会員（更新要ｶｸﾆﾝ）3ヶ月 | D38: 2025年07月 | E38: 8910
A39: まとめ継続 | B39: 自社分 | C39: 銀振会員（更新要ｶｸﾆﾝ）6ヶ月 | D39: 2025年07月 | E39: 222885
... A129: まとめ継続 | B129: 自社分 | C129: Apex年間会員（自動更新） | D129: 2026年09月 | E129: 46703

Sheet Sheet11(1月集計) 
A1: タイプ1 | B1: タイプ2 | C1: 商品名 | D1: 計上月 | E1: 合計金額
A2: まとめ継続 | B2: 全体売上 | C2: 3ヶ月会員（ライト・クレカ自動更新） | D2: 2025年02月 | E2: 19800
A3: まとめ継続 | B3: 全体売上 | C3: 6ヶ月会員（ライト・クレカ自動更新） | D3: 2025年02月 | E3: 38100
A4: まとめ継続 | B4: 全体売上 | C4: 銀振会員（更新要ｶｸﾆﾝ）3ヶ月 | D4: 2025年02月 | E4: 0
A5: まとめ継続 | B5: 自社分 | C5: 3ヶ月会員（ライト・クレカ自動更新） | D5: 2025年02月 | E5: 8910
A6: まとめ継続 | B6: 自社分 | C6: 6ヶ月会員（ライト・クレカ自動更新） | D6: 2025年02月 | E6: 17145
A7: まとめ継続 | B7: 自社分 | C7: 銀振会員（更新要ｶｸﾆﾝ）3ヶ月 | D7: 2025年02月 | E7: 0
A8: まとめ継続 | B8: 全体売上 | C8: 3ヶ月会員（ライト・クレカ自動更新） | D8: 2025年03月 | E8: 1821600
A9: まとめ継続 | B9: 全体売上 | C9: 6ヶ月会員（ライト・クレカ自動更新） | D9: 2025年03月 | E9: 533400
A10: まとめ継続 | B10: 全体売上 | C10: 銀振会員（更新要ｶｸﾆﾝ）3ヶ月 | D10: 2025年03月 | E10: 178200
A11: まとめ継続 | B11: 自社分 | C11: 3ヶ月会員（ライト・クレカ自動更新） | D11: 2025年03月 | E11: 819720
A12: まとめ継続 | B12: 自社分 | C12: 6ヶ月会員（ライト・クレカ自動更新） | D12: 2025年03月 | E12: 240030
A13: まとめ継続 | B13: 自社分 | C13: 銀振会員（更新要ｶｸﾆﾝ）3ヶ月 | D13: 2025年03月 | E13: 80190
... A107: まとめ継続 | B107: 自社分 | C107: Apex年間会員（自動更新） | D107: 2027年01月 | E107: 42457

Sheet まとめ継続(2月)
A1: 顧客ID | B1: GMO継続ID(LV) | C1: 顧客属性 | D1: 注文履歴 | E1: 配送履歴 | F1: 氏名 | G1: ふりがな | H1: 電話番号 | I1: 登録メールアドレス | J1: MD | K1: 予備メールアドレス | L1: 郵便番号 | M1: 都道府県 | N1: 住所（市区町村） | O1: それ以降の住所 | P1: GMO継続ID(JIS) | Q1: オプトイン | R1: 顧客登録日 | S1: CLEARTRADEコミュ会員タイプ | T1: CLEARTRADEコミュ退会日 | U1: 金額 | V1: 2025年3月 | W1: 2025年4月 | X1: 2025年5月 | Y1: 2025年6月 | Z1: 2025年7月 | AA1: 2025年8月 | AB1: 2025年9月 | AC1: 2025年10月 | AD1: 2025年11月 | AE1: 2025年12月 | AF1: 2026年1月 | AG1: 2026年2月 | AH1: 2026年3月 | AI1: 2025年3月 | AJ1: 2025年4月 | AK1: 2025年5月 | AL1: 2025年6月 | AM1: 2025年7月 | AN1: 2025年8月 | AO1: 2025年9月 | AP1: 2025年10月 | AQ1: 2025年11月 | AR1: 2025年12月 | AS1: 2026年1月 | AT1: 2026年2月 | AU1: 2026年3月 | AV1: 2026年4月 | AW1: 2026年5月 | AX1: 2026年6月 | AY1: 2026年7月 | AZ1: 2026年8月 | BA1: 2026年9月 | BB1: 2026年10月 | BC1: 2026年11月 | BD1: 2026年12月 | BE1: 2027年1月 | BF1: 2027年2月 | BG1: 2027年3月 | BH1: 億り人：相場研究会員タイプ | BI1: 億り人：相場研究退会日 | BJ1: りゅうじじデイトレ会員タイプ | BK1: りゅうじじデイトレ退会日 | BL1: 次世代知的投資家クラブ会員タイプ | BM1: 次世代知的投資家クラブ退会日 | BN1: 奥村尚の金融リテラシー会員タイプ | BO1: 奥村尚の金融リテラシー退会日 | BP1: CLEARエッセンシャル会員タイプ | BQ1: CLEARエッセンシャル退会日 | BR1: 大魔神会員タイプ | BS1: 大魔神退会日 | BT1: MSTP通信会員タイプ | BU1: MSTP通信退会日 | BV1: 高子ファミリー会員タイプ（プライスライン） | BW1: 高子ファミリー退会日 | BX1: 高子ファミリー【配信】会員タイプ | BY1: 高子ファミリー【配信】退会日 | BZ1: エバトレ会員タイプ | CA1: エバトレ退会日 | CB1: 秋田式ライトコース会員タイプ | CC1: 秋田式ライトコース退会日 | CD1: CLEARマスタープログラム分割会員 | CE1: CLEARマスタープログラム分割退会日 | CF1: トレンドサイン会員タイプ | CG1: トレンドサイン退会日 | CH1: PEAKFINDER会員タイプ | CI1: PEAKFINDER退会日 | CJ1: ADT継続会員タイプ | CK1: ADT継続退会日 | CM1: ＤＭ | CN1: メルマガ | CO1: 初回商品購入日 | CP1: 最終商品購入日 | CQ1: 在籍期間 | CR1: 売上累計 | CS1: 購入回数 | CT1: トレンドサインマスター講座：LINEアカウント
A2: C-00083249 | D2: 注文履歴 | E2: 配送履歴 | F2: 田辺博史 | G2: たなべひろふみ | H2: 8037680607 | I2: tanabe@yen-group.com | J2: https://mdpink.maildealer.jp/wapi.php | L2: 540-0004 | M2: 大阪府 | N2: 大阪市東成区中道 | O2: 1-10-10Hoxinpeace森ノ宮105 | Q2: res_youtube_mrk | R2: 45591 | S2: 6ヶ月会員（ライト・クレカ自動更新） | T2: 45889 | U2: 114300 | AB2: =+U2 -> 114300 | AO2: 19050 | AP2: 19050 | AQ2: 19050 | AR2: 19050 | AS2: 19050 | AT2: 19050 | CR2: 546600 | CS2: 2
A3: C-00081946 | D3: 注文履歴 | E3: 配送履歴 | F3: 山田世賢 | G3: やまだせいけん | H3: 9044161980 | I3: isohatago@yahoo.co.jp | J3: https://mdpink.maildealer.jp/wapi.php | L3: 115-0045 | M3: 東京都 | N3: 北区 | O3: 赤羽1-40-11-704 プレールドゥーク赤羽Ⅱ | Q3: res_youtube_mrk_seminar241005 | R3: 45538 | S3: 6ヶ月会員（ライト・クレカ自動更新） | T3: 45920 | U3: 114300 | AC3: =+U3 -> 114300 | AP3: 19050 | AQ3: 19050 | AR3: 19050 | AS3: 19050 | AT3: 19050 | AU3: 19050 | CR3: 551490 | CS3: 3
A4: C-00075126 | C4: ID重複用 | D4: 注文履歴 | E4: 配送履歴 | F4: 武田祐二 | G4: たけだゆうじ | H4: 9089580958 | I4: yellow.tail@docomo.ne.jp | J4: https://mdpink.maildealer.jp/wapi.php | L4: 421-0117 | M4: 静岡県 | N4: 静岡市駿河区下川原南 | O4: 45859 | Q4: res_youtube_mrk | R4: 45444 | S4: 3ヶ月会員（ライト・クレカ自動更新） | T4: 45767 | U4: 59400 | X4: =+U4 -> 59400 | AK4: 19800 | AL4: 19800 | AM4: 19800 | CR4: 59400 | CS4: 1
A5: C-00074947 | D5: 注文履歴 | E5: 配送履歴 | F5: 宮川美樹 | G5: みやかわよしき | H5: 8018828811 | I5: adgjmptw2001@gmail.com | J5: https://mdpink.maildealer.jp/wapi.php | L5: 005-0004 | M5: 北海道 | N5: 札幌市南区澄川4条 | O5: 3丁目8-44-1 | Q5: res_youtube_mrk | R5: 45447 | S5: 3ヶ月会員（ライト・クレカ自動更新） | T5: 45736 | U5: 59400 | W5: =+U5 -> 59400 | AJ5: 19800 | AK5: 19800 | AL5: 19800 | CR5: 491700 | CS5: 7
A6: C-00074945 | D6: 注文履歴 | E6: 配送履歴 | F6: 岩崎由美子 | G6: いわさきゆみこ | H6: 9069630121 | I6: kouandryuu@gmail.com | J6: https://mdpink.maildealer.jp/wapi.php | L6: 651-2135 | M6: 兵庫県 | N6: 神戸市西区王塚台 | O6: 2-13-10 | Q6: res_youtube_mrk | R6: 45447 | S6: 3ヶ月会員（ライト・クレカ自動更新） | T6: 45736 | U6: 59400 | W6: =+U6 -> 59400 | AJ6: 19800 | AK6: 19800 | AL6: 19800 | CR6: 491700 | CS6: 2
A7: C-00074942 | D7: 注文履歴 | E7: 配送履歴 | F7: 藤山貴浩 | G7: ふじやまたかひろ | H7: 8012788103 | I7: akeboshi06@gmail.com | J7: https://mdpink.maildealer.jp/wapi.php | L7: 341-0002 | M7: 埼玉県 | N7: 三郷市彦音 | O7: 2-25-2 ルーラルパーク301 | Q7: res_youtube | R7: 45447 | S7: 3ヶ月会員（ライト・クレカ自動更新） | T7: 45736 | U7: 59400 | W7: =+U7 -> 59400 | AJ7: 19800 | AK7: 19800 | AL7: 19800 | CR7: 491700 | CS7: 7
A8: C-00074941 | D8: 注文履歴 | E8: 配送履歴 | F8: 橋本公洋 | G8: はしもときみひろ | H8: 9070642282 | I8: kisss642_ipad@icloud.com | J8: https://mdpink.maildealer.jp/wapi.php | L8: 962-0401 | M8: 福島県 | N8: 須賀川市 | O8: 向陽町642 | Q8: res_youtube_mrk | R8: 45447 | S8: 6ヶ月会員（ライト・クレカ自動更新） | T8: 45828 | U8: 114300 | Z8: =+U8 -> 114300 | AM8: 19050 | AN8: 19050 | AO8: 19050 | AP8: 19050 | AQ8: 19050 | AR8: 19050 | CR8: 546600 | CS8: 2
A9: C-00074937 | D9: 注文履歴 | E9: 配送履歴 | F9: 今泉宏章 | G9: いまいずみひろあき | H9: 9091911429 | I9: botzehrc@yahoo.co.jp | J9: https://mdpink.maildealer.jp/wapi.php | L9: 447-0012 | M9: 埼玉県 | N9: 加須市 | O9: 45659 | Q9: res_youtube_mrk | R9: 45447 | S9: 銀振会員（更新要ｶｸﾆﾝ）6ヶ月 | T9: 45828 | U9: 114300 | Z9: =+U9 -> 114300 | AM9: 19050 | AN9: 19050 | AO9: 19050 | AP9: 19050 | AQ9: 19050 | AR9: 19050 | CR9: 432300 | CS9: 1
A10: C-00074934 | D10: 注文履歴 | E10: 配送履歴 | F10: 廣田雅美 | G10: ひろたまさみ | H10: 9054692739 | I10: meru01312001@yahoo.co.jp | J10: https://mdpink.maildealer.jp/wapi.php | L10: 646-1417 | M10: 和歌山県 | N10: 田辺市中辺路町川合 | O10: 1532 | Q10: res_youtube_mrk | R10: 45447 | S10: 6ヶ月会員（ライト・クレカ自動更新） | T10: 45828 | U10: 114300 | Z10: =+U10 -> 114300 | AM10: 19050 | AN10: 19050 | AO10: 19050 | AP10: 19050 | AQ10: 19050 | AR10: 19050 | CR10: 546600 | CS10: 3
A11: C-00074931 | D11: 注文履歴 | E11: 配送履歴 | F11: 帆苅正典 | G11: ほかりまさのり | H11: 9044761520 | I11: nor.ism@icloud.com | J11: https://mdpink.maildealer.jp/wapi.php | L11: 314-0143 | M11: 茨城県 | N11: 神栖市 | O11: 神栖13-22 ミリオンファミリーズ105 | Q11: res_youtube_mrk | R11: 45447 | S11: 6ヶ月会員（ライト・クレカ自動更新） | T11: 45828 | U11: 114300 | Z11: =+U11 -> 114300 | AM11: 19050 | AN11: 19050 | AO11: 19050 | AP11: 19050 | AQ11: 19050 | AR11: 19050 | CR11: 546600 | CS11: 3
A12: C-00074928 | D12: 注文履歴 | E12: 配送履歴 | F12: 吉田努 | G12: よしだつとむ | H12: 9043850274 | I12: yoshimoo732507@gmail.com | J12: https://mdpink.maildealer.jp/wapi.php | L12: 113-0023 | M12: 東京都 | N12: 文京区向丘 | O12: 2-34-1 エスタジオ本駒込302 | Q12: res_youtube_mrk | R12: 45447 | S12: 6ヶ月会員（ライト・クレカ自動更新） | T12: 45828 | U12: 114300 | Z12: =+U12 -> 114300 | AM12: 19050 | AN12: 19050 | AO12: 19050 | AP12: 19050 | AQ12: 19050 | AR12: 19050 | CR12: 546600 | CS12: 2
A13: C-00074922 | D13: 注文履歴 | E13: 配送履歴 | F13: 上野利仁 | G13: うえのとしひと | H13: 9014964243 | I13: toshi.hit.u@gmail.com | J13: https://mdpink.maildealer.jp/wapi.php | L13: 321-0111 | M13: 栃木県 | N13: 宇都宮市 | O13: 川田町111ー2 | Q13: res_youtube_mrk | R13: 45447 | S13: 6ヶ月会員（ライト・クレカ自動更新） | T13: 45828 | U13: 114300 | Z13: =+U13 -> 114300 | AM13: 19050 | AN13: 19050 | AO13: 19050 | AP13: 19050 | AQ13: 19050 | AR13: 19050 | CR13: 546600 | CS13: 2
A14: C-00074920 | D14: 注文履歴 | E14: 配送履歴 | F14: 谷田昌広 | G14: たにだまさひろ | H14: 9091991825 | I14: tanidakagu1@gmail.com | J14: https://mdpink.maildealer.jp/wapi.php | L14: 444-3433 | M14: 愛知県 | N14: 岡崎市 | O14: 木下町字竹ノ花41 | Q14: res_youtube_mrk | R14: 45447 | S14: （退会済）月額ライト | T14: 45706 | CR14: 453270 | CS14: 7
A15: C-00074916 | D15: 注文履歴 | E15: 配送履歴 | F15: 近藤洋文 | G15: こんどうひろふみ | H15: 9095010677 | I15: kkdental1122@gmail.com | J15: https://mdpink.maildealer.jp/wapi.php | L15: 600-8415 | M15: 京都府 | N15: 京都市下京区 | O15: 因幡堂町677イスケビル2階 | Q15: res_youtube_mrk | R15: 45447 | S15: 銀振会員（更新要ｶｸﾆﾝ）3ヶ月 | T15: 45736 | U15: 59400 | W15: =+U15 -> 59400 | AJ15: 19800 | AK15: 19800 | AL15: 19800 | CR15: 491700 | CS15: 2
A16: C-00074914 | D16: 注文履歴 | E16: 配送履歴 | F16: 西村与志郎 | G16: にしむらよしろう | H16: 9040250328 | I16: jl3sik@gmail.com | J16: https://mdpink.maildealer.jp/wapi.php | L16: 565-0863 | M16: 大阪府 | N16: 吹田市竹見台 | O16: 4丁目2-6 | Q16: res_youtube_mrk | R16: 45447 | S16: 6ヶ月会員（ライト・クレカ自動更新） | T16: 45858 | U16: 114300 | AA16: =+U16 -> 114300 | AN16: 19050 | AO16: 19050 | AP16: 19050 | AQ16: 19050 | AR16: 19050 | AS16: 19050 | CR16: 567570 | CS16: 3
A17: C-00074905 | D17: 注文履歴 | E17: 配送履歴 | F17: 實平哲也 | G17: さねひらてつや | H17: 8047165868 | I17: sanetti25th@yahoo.co.jp | J17: https://mdpink.maildealer.jp/wapi.php | L17: 252-0344 | M17: 神奈川県 | N17: 相模原市南区古淵 | O17: 2-3-7T&T第二ビル205 | Q17: res_youtube_mrk | R17: 45447 | S17: 6ヶ月会員（ライト・クレカ自動更新） | T17: 45889 | U17: 114300 | AB17: =+U17 -> 114300 | AO17: 19050 | AP17: 19050 | AQ17: 19050 | AR17: 19050 | AS17: 19050 | AT17: 19050 | CR17: 546600 | CS17: 2
A18: C-00074903 | D18: 注文履歴 | E18: 配送履歴 | F18: コーンみさ | G18: こーんみさ | H18: 8089539757 | I18: misanino2@gmail.com | J18: https://mdpink.maildealer.jp/wapi.php | L18: 96701 | M18: 東京都 | N18: Onikiniki Way Aiea | O18: 98-1411 | Q18: res_youtube_mrk | R18: 45447 | S18: 3ヶ月会員（ライト・クレカ自動更新） | T18: 45736 | U18: 59400 | W18: =+U18 -> 59400 | AJ18: 19800 | AK18: 19800 | AL18: 19800 | CR18: 491700 | CS18: 2
A19: C-00074901 | D19: 注文履歴 | E19: 配送履歴 | F19: 佐藤誠 | G19: さとうまこと | H19: 8064027748 | I19: Wa87253iop@yahoo.co.jp | J19: https://mdpink.maildealer.jp/wapi.php | L19: 234-0003 | M19: 神奈川県 | N19: 横浜市港南区港南 | O19: 2-15-10 204号 | Q19: res_youtube_mrk | R19: 45447 | S19: 6ヶ月会員（ライト・クレカ自動更新） | T19: 45828 | U19: 114300 | Z19: =+U19 -> 114300 | AM19: 19050 | AN19: 19050 | AO19: 19050 | AP19: 19050 | AQ19: 19050 | AR19: 19050 | CR19: 546600 | CS19: 4
A20: C-00074897 | D20: 注文履歴 | E20: 配送履歴 | F20: 山野操 | G20: やまのみさお | H20: 9066084616 | I20: yamanoimo2@gmail.com | J20: https://mdpink.maildealer.jp/wapi.php | L20: 542-0083 | M20: 大阪府 | N20: 中央区東心斎橋 | O20: 1-3-3, ブランズタワーウェリス心斎橋South704 | Q20: res_youtube_mrk | R20: 45447 | S20: 6ヶ月会員（ライト・クレカ自動更新） | T20: 45828 | U20: 114300 | Z20: =+U20 -> 114300 | AM20: 19050 | AN20: 19050 | AO20: 19050 | AP20: 19050 | AQ20: 19050 | AR20: 19050 | CR20: 546600 | CS20: 7
A21: C-00074892 | D21: 注文履歴 | E21: 配送履歴 | F21: 若松俊宏 | G21: わかまつとしひろ | H21: 9095406258 | I21: volken3535@i.softbank.jp | J21: https://mdpink.maildealer.jp/wapi.php | L21: 605-0913 | M21: 京都府 | N21: 京都市東山区石垣町東側 | O21: 60 | Q21: res_youtube_mrk | R21: 45447 | S21: 6ヶ月会員（ライト・クレカ自動更新） | T21: 45828 | U21: 114300 | Z21: =+U21 -> 114300 | AM21: 19050 | AN21: 19050 | AO21: 19050 | AP21: 19050 | AQ21: 19050 | AR21: 19050 | CR21: 432300 | CS21: 6
A22: C-00074891 | D22: 注文履歴 | E22: 配送履歴 | F22: 宮川宏美 | G22: みやがわひろみ | H22: 8014999421 | I22: sabu.miyabi.no@gmail.com | J22: https://mdpink.maildealer.jp/wapi.php | L22: 617-0002 | M22: 京都府 | N22: 向日市寺戸町西野辺 | O22: 21-14シャルマンコート202 | Q22: res_youtube_mrk | R22: 45447 | S22: 3ヶ月会員（ライト・クレカ自動更新） | T22: 45736 | U22: 59400 | W22: =+U22 -> 59400 | AJ22: 19800 | AK22: 19800 | AL22: 19800 | CR22: 491700 | CS22: 3
A23: C-00074889 | D23: 注文履歴 | E23: 配送履歴 | F23: 塩田芳江 | G23: しおだよしえ | H23: 9087020938 | I23: yoi@yahoo.co.jp | J23: https://mdpink.maildealer.jp/wapi.php | L23: 910-0015 | M23: 福井県 | N23: 福井市 | O23: 二ノ宮2-15-18A-1 | Q23: res_youtube_mrk | R23: 45447 | S23: 銀振会員（更新要ｶｸﾆﾝ）6ヶ月 | T23: 45828 | U23: 114300 | Z23: =+U23 -> 114300 | AM23: 19050 | AN23: 19050 | AO23: 19050 | AP23: 19050 | AQ23: 19050 | AR23: 19050 | CR23: 546600 | CS23: 2
A24: C-00074888 | D24: 注文履歴 | E24: 配送履歴 | F24: 本目毅 | G24: ほんめつよし | H24: 9040904687 | I24: tsu.honme@gmail.com | J24: https://mdpink.maildealer.jp/wapi.php | L24: 350-0807 | M24: 埼玉県 | N24: 川越市大字吉田 | O24: 185-6 ゼフィール101 | Q24: res_youtube_mrk | R24: 45447 | S24: 銀振会員（更新要ｶｸﾆﾝ）3ヶ月 | T24: 45736 | U24: 59400 | W24: =+U24 -> 59400 | AJ24: 19800 | AK24: 19800 | AL24: 19800 | CR24: 491700 | CS24: 2
A25: C-00074887 | D25: 注文履歴 | E25: 配送履歴 | F25: 檀高博 | G25: だんたかひろ | H25: 9093940688 | I25: taka.dan.2709.dragon@gmail.com | J25: https://mdpink.maildealer.jp/wapi.php | L25: 245-0014 | M25: 神奈川県 | N25: 横浜市泉区 | O25: 中田南1-1-16-201 | Q25: res_youtube_mrk | R25: 45447 | S25: 3ヶ月会員（ライト・クレカ自動更新） | T25: 45736 | U25: 59400 | W25: =+U25 -> 59400 | AJ25: 19800 | AK25: 19800 | AL25: 19800 | CR25: 491700 | CS25: 7
A26: C-00074886 | D26: 注文履歴 | E26: 配送履歴 | F26: 中嶋啓博 | G26: なかじまあきひろ | H26: 9073082308 | I26: sirube73@gmail.com | J26: https://mdpink.maildealer.jp/wapi.php | L26: 465-0073 | M26: 愛知県 | N26: 名古屋市名東区 | O26: 高針原1-801 | Q26: res_youtube_mrk | R26: 45447 | S26: （退会済）月額ライト | T26: 45706 | CR26: 474240 | CS26: 8
A27: C-00074885 | D27: 注文履歴 | E27: 配送履歴 | F27: 工藤貴之 | G27: くどうたかゆき | H27: 8018011746 | I27: mcm1801qlo1746@gmail.com | J27: https://mdpink.maildealer.jp/wapi.php | L27: 997-0821 | M27: 山形県 | N27: 鶴岡市三光町 | O27: 45752 | Q27: res_youtube_mrk | R27: 45447 | S27: 6ヶ月会員（ライト・クレカ自動更新） | T27: 45828 | U27: 114300 | Z27: =+U27 -> 114300 | AM27: 19050 | AN27: 19050 | AO27: 19050 | AP27: 19050 | AQ27: 19050 | AR27: 19050 | CR27: 432300 | CS27: 6
A28: C-00074881 | D28: 注文履歴 | E28: 配送履歴 | F28: 馬場昭江 | G28: ばばあきえ | H28: 9094220703 | I28: akiebaba@ybb.ne.jp | J28: https://mdpink.maildealer.jp/wapi.php | L28: 014-0333 | M28: 秋田県 | N28: 仙北市角館町川原町 | O28: 21186 | Q28: res_youtube_mrk | R28: 45447 | S28: 6ヶ月会員（ライト・クレカ自動更新） | T28: 45828 | U28: 114300 | Z28: =+U28 -> 114300 | AM28: 19050 | AN28: 19050 | AO28: 19050 | AP28: 19050 | AQ28: 19050 | AR28: 19050 | CR28: 546600 | CS28: 2
A29: C-00074876 | D29: 注文履歴 | E29: 配送履歴 | F29: 景山康司 | G29: かげやまやすじ | H29: 9071260021 | I29: ha_sekai@yahoo.co.jp | J29: https://mdpink.maildealer.jp/wapi.php | L29: 733-0002 | M29: 広島県 | N29: 広島市西区楠木町 | O29: 4-9-8 リバーサイドパーク楠木 | Q29: res_youtube_mrk | R29: 45447 | S29: 3ヶ月会員（ライト・クレカ自動更新） | T29: 45736 | U29: 59400 | W29: =+U29 -> 59400 | AJ29: 19800 | AK29: 19800 | AL29: 19800 | CR29: 432300 | CS29: 1
A30: C-00074871 | D30: 注文履歴 | E30: 配送履歴 | F30: 山口裕紀 | G30: やまぐちゆき | H30: 9056243606 | I30: yukky.minnie@gmail.com | J30: https://mdpink.maildealer.jp/wapi.php | L30: 470-0135 | M30: 愛知県 | N30: 日進岩崎台 | O30: 2-1306-17 | Q30: res_youtube_mrk | R30: 45447 | S30: （退会済）月額ライト | T30: 45705 | CR30: 474240 | CS30: 8
A31: C-00074870 | D31: 注文履歴 | E31: 配送履歴 | F31: 中馬宏昌 | G31: ちゅうまひろまさ | H31: 8053842109 | I31: arms2678@gmail.com | J31: https://mdpink.maildealer.jp/wapi.php | L31: 223-0064 | M31: 神奈川県 | N31: 横浜市港北区下田町 | O31: 3-13-18 | Q31: res_youtube_mrk | R31: 45447 | S31: 6ヶ月会員（ライト・クレカ自動更新） | T31: 45828 | U31: 114300 | Z31: =+U31 -> 114300 | AM31: 19050 | AN31: 19050 | AO31: 19050 | AP31: 19050 | AQ31: 19050 | AR31: 19050 | CR31: 546600 | CS31: 7
A32: C-00074863 | D32: 注文履歴 | E32: 配送履歴 | F32: 作田圭治 | G32: さくだけいじ | H32: 9042906316 | I32: sakusaku7ks@outlook.jp | J32: https://mdpink.maildealer.jp/wapi.php | L32: 555-0001 | M32: 大阪府 | N32: 大阪市西淀川区佃 | O32: 45782 | Q32: res_youtube_mrk | R32: 45447 | S32: 銀振会員（更新要ｶｸﾆﾝ）6ヶ月 | T32: 45828 | U32: 114300 | Z32: =+U32 -> 114300 | AM32: 19050 | AN32: 19050 | AO32: 19050 | AP32: 19050 | AQ32: 19050 | AR32: 19050 | CR32: 546600 | CS32: 2
A33: C-00074859 | D33: 注文履歴 | E33: 配送履歴 | F33: 黒田真道 | G33: くろだまさみち | H33: 8075088042 | I33: shindou19900120@yahoo.co.jp | J33: https://mdpink.maildealer.jp/wapi.php | L33: 093-0033 | M33: 北海道 | N33: 網走市駒場北 | O33: 37989 | Q33: res_youtube_mrk | R33: 45447 | S33: 6ヶ月会員（ライト・クレカ自動更新） | T33: 45828 | U33: 114300 | Z33: =+U33 -> 114300 | AM33: 19050 | AN33: 19050 | AO33: 19050 | AP33: 19050 | AQ33: 19050 | AR33: 19050 | CR33: 546600 | CS33: 7
A34: C-00074855 | D34: 注文履歴 | E34: 配送履歴 | F34: 大野木俊介 | G34: おおのきしゅんすけ | H34: 9054587245 | I34: shunsukeonoki@gmail.com | J34: https://mdpink.maildealer.jp/wapi.php | L34: 430-0929 | M34: 静岡県 | N34: 浜松市中央区木戸町 | O34: 45876 | Q34: res_youtube_mrk | R34: 45447 | S34: 6ヶ月会員（ライト・クレカ自動更新） | T34: 45828 | U34: 114300 | Z34: =+U34 -> 114300 | AM34: 19050 | AN34: 19050 | AO34: 19050 | AP34: 19050 | AQ34: 19050 | AR34: 19050 | CR34: 664300 | CS34: 2
A35: C-00074854 | D35: 注文履歴 | E35: 配送履歴 | F35: 藤井成行 | G35: ふじいなりゆき | H35: 9079925252 | I35: nariyvki@gmail.com | J35: https://mdpink.maildealer.jp/wapi.php | L35: 565-0804 | M35: 大阪府 | N35: 吹田市新芦屋上 | O35: 13-8-602 | Q35: res_youtube_mrk | R35: 45447 | S35: 6ヶ月会員（ライト・クレカ自動更新） | T35: 45828 | U35: 114300 | Z35: =+U35 -> 114300 | AM35: 19050 | AN35: 19050 | AO35: 19050 | AP35: 19050 | AQ35: 19050 | AR35: 19050 | CR35: 664300 | CS35: 2
A36: C-00074851 | D36: 注文履歴 | E36: 配送履歴 | F36: 浅田貴大 | G36: あさだたかひろ | H36: 8050868922 | I36: takahiro_a_3_9@hotmail.com | J36: https://mdpink.maildealer.jp/wapi.php | L36: 260-0002 | M36: 千葉県 | N36: 千葉市中央区旭町 | O36: 45870 | Q36: res_youtube_mrk | R36: 45447 | S36: 6ヶ月会員（ライト・クレカ自動更新） | T36: 45828 | U36: 114300 | Z36: =+U36 -> 114300 | AM36: 19050 | AN36: 19050 | AO36: 19050 | AP36: 19050 | AQ36: 19050 | AR36: 19050 | CR36: 546600 | CS36: 2
A37: C-00074843 | D37: 注文履歴 | E37: 配送履歴 | F37: 津田祐一 | G37: つだゆういち | H37: 9014767965 | I37: sin.g0jig0ji@gmail.com | J37: https://mdpink.maildealer.jp/wapi.php | L37: 732-0065 | M37: 広島県 | N37: 広島市東区牛田中 | O37: 37388 | Q37: res_youtube_mrk | R37: 45447 | S37: 6ヶ月会員（ライト・クレカ自動更新） | T37: 45828 | U37: 114300 | Z37: =+U37 -> 114300 | AM37: 19050 | AN37: 19050 | AO37: 19050 | AP37: 19050 | AQ37: 19050 | AR37: 19050 | CR37: 664300 | CS37: 2
A38: C-00074842 | D38: 注文履歴 | E38: 配送履歴 | F38: 上野裕之 | G38: うえのひろゆき | H38: 9074217982 | I38: vw.16890827@gmail.com | J38: https://mdpink.maildealer.jp/wapi.php | L38: 321-4364 | M38: 栃木県 | N38: 真岡市 | O38: 長田 1-10-6 | Q38: res_youtube_mrk | R38: 45446 | S38: 6ヶ月会員（ライト・クレカ自動更新） | T38: 45828 | U38: 114300 | Z38: =+U38 -> 114300 | AM38: 19050 | AN38: 19050 | AO38: 19050 | AP38: 19050 | AQ38: 19050 | AR38: 19050 | CR38: 546600 | CS38: 7
A39: C-00074841 | D39: 注文履歴 | E39: 配送履歴 | F39: 南出基志 | G39: みなみでもとし | H39: 7084048033 | I39: rumraisin422@gmail.com | J39: https://mdpink.maildealer.jp/wapi.php | L39: 640-8358 | M39: 和歌山県 | N39: 和歌山市 | O39: 北ノ新地下六軒丁12 | Q39: res_youtube_mrk | R39: 45446 | S39: 6ヶ月会員（ライト・クレカ自動更新） | T39: 45828 | U39: 114300 | Z39: =+U39 -> 114300 | AM39: 19050 | AN39: 19050 | AO39: 19050 | AP39: 19050 | AQ39: 19050 | AR39: 19050 | CR39: 546600 | CS39: 2
A40: C-00074838 | D40: 注文履歴 | E40: 配送履歴 | F40: 渋谷昇 | G40: しぶやのぼる | H40: 8034559878 | I40: supi2016nz@yahoo.co.jp | J40: https://mdpink.maildealer.jp/wapi.php | L40: 353-0007 | M40: 埼玉県 | N40: 志木市柏町 | O40: 38852 | Q40: res_youtube_mrk | R40: 45446 | S40: 6ヶ月会員（ライト・クレカ自動更新） | T40: 45828 | U40: 114300 | Z40: =+U40 -> 114300 | AM40: 19050 | AN40: 19050 | AO40: 19050 | AP40: 19050 | AQ40: 19050 | AR40: 19050 | CR40: 546600 | CS40: 2
...

Sheet まとめ継続(分割計上計算)(2月)
B3: 列ラベル
A4: 値 | B4: 3ヶ月会員（ライト・クレカ自動更新） | C4: 6ヶ月会員（ライト・クレカ自動更新） | D4: Apex年間会員（自動更新） | E4: 銀振会員（更新要ｶｸﾆﾝ）3ヶ月 | F4: 銀振会員（更新要ｶｸﾆﾝ）6ヶ月 | G4: 銀振会員（更新要ｶｸﾆﾝ）Apex年間 | H4: 総計
A5: 合計 / 2025年3月 | C5: 38100 | H5: 38100
A6: 合計 / 2025年4月 | B6: 1544400 | C6: 533400 | E6: 178200 | H6: 2256000
A7: 合計 / 2025年5月 | B7: 2019600 | C7: 2990850 | D7: 56610 | E7: 198000 | F7: 76200 | H7: 5341260
A8: 合計 / 2025年6月 | B8: 2059200 | C8: 3162300 | D8: 84915 | E8: 198000 | F8: 76200 | H8: 5580615
A9: 合計 / 2025年7月 | B9: 514800 | C9: 9315450 | D9: 84915 | E9: 19800 | F9: 495300 | H9: 10430265
A10: 合計 / 2025年8月 | B10: 39600 | C10: 9429750 | D10: 94350 | F10: 495300 | H10: 10059000
A11: 合計 / 2025年9月 | C11: 9486900 | D11: 245310 | F11: 495300 | G11: 28305 | H11: 10255815
A12: 合計 / 2025年10月 | C12: 9010650 | D12: 245310 | F12: 495300 | G12: 28305 | H12: 9779565
A13: 合計 / 2025年11月 | C13: 6553200 | D13: 245310 | F13: 419100 | G13: 28305 | H13: 7245915
A14: 合計 / 2025年12月 | C14: 6381750 | D14: 254745 | F14: 419100 | G14: 28305 | H14: 7083900
A15: 合計 / 2026年1月 | C15: 228600 | D15: 254745 | G15: 28305 | H15: 511650
A16: 合計 / 2026年2月 | C16: 114300 | D16: 254745 | G16: 28305 | H16: 397350
A17: 合計 / 2026年3月 | C17: 19050 | D17: 349095 | G17: 28305 | H17: 396450
A18: 合計 / 2026年4月 | D18: 349095 | G18: 28305 | H18: 377400
A19: 合計 / 2026年5月 | D19: 292485 | G19: 28305 | H19: 320790
A20: 合計 / 2026年6月 | D20: 264180 | G20: 28305 | H20: 292485
A21: 合計 / 2026年7月 | D21: 264180 | G21: 28305 | H21: 292485
A22: 合計 / 2026年8月 | D22: 254745 | G22: 28305 | H22: 283050
A23: 合計 / 2026年9月 | D23: 103785 | H23: 103785
A24: 合計 / 2026年10月 | D24: 103785 | H24: 103785
A25: 合計 / 2026年11月 | D25: 103785 | H25: 103785
A26: 合計 / 2026年12月 | D26: 94350 | H26: 94350
A27: 合計 / 2027年1月 | D27: 94350 | H27: 94350
A28: 合計 / 2027年2月 | D28: 94350 | H28: 94350
A29: 合計 / 2027年3月

Sheet Sheet8
A4: 合計 / 合計金額 | B4: 列ラベル
A5: 行ラベル | B5: 自社分 | C5: 全体売上 | D5: 総計
A6: 2025年02月 | B6: 26055 | C6: 57900 | D6: 83955
A7: 2025年03月 | B7: 1139940 | C7: 2533200 | D7: 3673140
A8: 2025年04月 | B8: 2536879 | C8: 5637510 | D8: 8174389
A9: 2025年05月 | B9: 2626768 | C9: 5837265 | D9: 8464033
A10: 2025年06月 | B10: 4701853 | C10: 10448565 | D10: 15150418
A11: 2025年07月 | B11: 4534784 | C11: 10077300 | D11: 14612084
A12: 2025年08月 | B12: 4585234 | C12: 10189410 | D12: 14774644
A13: 2025年09月 | B13: 4362349 | C13: 9694110 | D13: 14056459
A14: 2025年10月 | B14: 3213634 | C14: 7141410 | D14: 10355044
A15: 2025年11月 | B15: 3136481 | C15: 6969960 | D15: 10106441
A16: 2025年12月 | B16: 174642 | C16: 388095 | D16: 562737
A17: 2026年01月 | B17: 123207 | C17: 273795 | D17: 397002
... A30: 総計 | B30: 32231751 | C30: 71626140 | D30: 103857891

Sheet Sheet1-2
A1: タイプ1 | B1: タイプ2 | C1: 商品名 | D1: 計上月 | E1: 合計金額
A2: まとめ継続 | B2: 全体売上 | C2: 3ヶ月会員（ライト・クレカ自動更新） | D2: 2025年02月 | E2: 59400
A3: まとめ継続 | B3: 全体売上 | C3: 3ヶ月会員（ライト・クレカ自動更新） | D3: 2025年03月 | E3: 5405400
A4: まとめ継続 | B4: 全体売上 | C4: 3ヶ月会員（ライト・クレカ自動更新） | D4: 2025年04月 | E4: 1425600
A5: まとめ継続 | B5: 全体売上 | C5: 3ヶ月会員（ライト・クレカ自動更新） | D5: 2025年05月 | E5: 59400
A6: まとめ継続 | B6: 全体売上 | C6: 6ヶ月会員（ライト・クレカ自動更新） | D6: 2025年02月 | E6: 228600
A7: まとめ継続 | B7: 全体売上 | C7: 6ヶ月会員（ライト・クレカ自動更新） | D7: 2025年03月 | E7: 2971800
A8: まとめ継続 | B8: 全体売上 | C8: 6ヶ月会員（ライト・クレカ自動更新） | D8: 2025年04月 | E8: 14859000
A9: まとめ継続 | B9: 全体売上 | C9: 6ヶ月会員（ライト・クレカ自動更新） | D9: 2025年05月 | E9: 1028700
A10: まとめ継続 | B10: 全体売上 | C10: 6ヶ月会員（ライト・クレカ自動更新） | D10: 2025年06月 | E10: 37033200
A11: まとめ継続 | B11: 全体売上 | C11: 6ヶ月会員（ライト・クレカ自動更新） | D11: 2025年07月 | E11: 685800
A12: まとめ継続 | B12: 全体売上 | C12: 6ヶ月会員（ライト・クレカ自動更新） | D12: 2025年08月 | E12: 114300
A13: まとめ継続 | B13: 全体売上 | C13: Apex年間会員（自動更新） | D13: 2025年04月 | E13: 679320
... A22: まとめ継続 | B22: 全体売上 | C22: 銀振会員（更新要ｶｸﾆﾝ）6ヶ月 | D22: 2025年06月 | E22: 2514600

Sheet Sheet1
A1: タイプ1 | B1: タイプ2 | C1: 商品名 | D1: 計上月 | E1: 合計金額
A2: まとめ継続 | B2: 全体売上 | C2: 3ヶ月会員（ライト・クレカ自動更新） | D2: 2025年02月 | E2: 19800
A3: まとめ継続 | B3: 全体売上 | C3: 3ヶ月会員（ライト・クレカ自動更新） | D3: 2025年03月 | E3: 1821600
A4: まとめ継続 | B4: 全体売上 | C4: 3ヶ月会員（ライト・クレカ自動更新） | D4: 2025年04月 | E4: 2296800
A5: まとめ継続 | B5: 全体売上 | C5: 3ヶ月会員（ライト・クレカ自動更新） | D5: 2025年05月 | E5: 2296800
A6: まとめ継続 | B6: 全体売上 | C6: 3ヶ月会員（ライト・クレカ自動更新） | D6: 2025年06月 | E6: 495000
A7: まとめ継続 | B7: 全体売上 | C7: 3ヶ月会員（ライト・クレカ自動更新） | D7: 2025年07月 | E7: 19800
A8: まとめ継続 | B8: 全体売上 | C8: 6ヶ月会員（ライト・クレカ自動更新） | D8: 2025年02月 | E8: 38100
A9: まとめ継続 | B9: 全体売上 | C9: 6ヶ月会員（ライト・クレカ自動更新） | D9: 2025年03月 | E9: 533400
A10: まとめ継続 | B10: 全体売上 | C10: 6ヶ月会員（ライト・クレカ自動更新） | D10: 2025年04月 | E10: 3009900
A11: まとめ継続 | B11: 全体売上 | C11: 6ヶ月会員（ライト・クレカ自動更新） | D11: 2025年05月 | E11: 3181350
A12: まとめ継続 | B12: 全体売上 | C12: 6ヶ月会員（ライト・クレカ自動更新） | D12: 2025年06月 | E12: 9353550
A13: まとめ継続 | B13: 全体売上 | C13: 6ヶ月会員（ライト・クレカ自動更新） | D13: 2025年07月 | E13: 9467850
... A54: まとめ継続 | B54: 全体売上 | C54: 銀振会員（更新要ｶｸﾆﾝ）6ヶ月 | D54: 2025年11月 | E54: 419100

Sheet Sheet2
A1: タイプ1 | B1: タイプ2 | C1: 商品名 | D1: 計上月 | E1: 合計金額
A2: まとめ継続 | B2: 自社分 | C2: 3ヶ月会員（ライト・クレカ自動更新） | D2: 2025年02月 | E2: 8910
A3: まとめ継続 | B3: 自社分 | C3: 3ヶ月会員（ライト・クレカ自動更新） | D3: 2025年03月 | E3: 819720
A4: まとめ継続 | B4: 自社分 | C4: 3ヶ月会員（ライト・クレカ自動更新） | D4: 2025年04月 | E4: 1033560
A5: まとめ継続 | B5: 自社分 | C5: 3ヶ月会員（ライト・クレカ自動更新） | D5: 2025年05月 | E5: 1033560
A6: まとめ継続 | B6: 自社分 | C6: 3ヶ月会員（ライト・クレカ自動更新） | D6: 2025年06月 | E6: 222750 | T6: 45
A7: まとめ継続 | B7: 自社分 | C7: 3ヶ月会員（ライト・クレカ自動更新） | D7: 2025年07月 | E7: 8910
A8: まとめ継続 | B8: 自社分 | C8: 6ヶ月会員（ライト・クレカ自動更新） | D8: 2025年02月 | E8: 17145
A9: まとめ継続 | B9: 自社分 | C9: 6ヶ月会員（ライト・クレカ自動更新） | D9: 2025年03月 | E9: 240030
A10: まとめ継続 | B10: 自社分 | C10: 6ヶ月会員（ライト・クレカ自動更新） | D10: 2025年04月 | E10: 1354455
A11: まとめ継続 | B11: 自社分 | C11: 6ヶ月会員（ライト・クレカ自動更新） | D11: 2025年05月 | E11: 1431607
A12: まとめ継続 | B12: 自社分 | C12: 6ヶ月会員（ライト・クレカ自動更新） | D12: 2025年06月 | E12: 4209097
A13: まとめ継続 | B13: 自社分 | C13: 6ヶ月会員（ライト・クレカ自動更新） | D13: 2025年07月 | E13: 4260532
A14: まとめ継続 | B14: 自社分 | C14: 6ヶ月会員（ライト・クレカ自動更新） | D14: 2025年08月 | E14: 4251960
A15: まとめ継続 | B15: 自社分 | C15: 6ヶ月会員（ライト・クレカ自動更新） | D15: 2025年09月 | E15: 4029075
A16: まとめ継続 | B16: 自社分 | C16: 6ヶ月会員（ライト・クレカ自動更新） | D16: 2025年10月 | E16: 2914650
A17: まとめ継続 | B17: 自社分 | C17: 6ヶ月会員（ライト・クレカ自動更新） | D17: 2025年11月 | E17: 2837497
A18: まとめ継続 | B18: 自社分 | C18: 6ヶ月会員（ライト・クレカ自動更新） | D18: 2025年12月 | E18: 60007
... A54: まとめ継続 | B54: 自社分 | C54: 銀振会員（更新要ｶｸﾆﾝ）6ヶ月 | D54: 2025年11月 | E54: 188595

Sheet まとめ継続(分割計上計算)
A1: 氏名 | B1: (複数のアイテム)
A3: 行ラベル | B3: 合計 / 2025年2月2 | C3: 合計 / 2025年3月2 | D3: 合計 / 2025年4月2 | E3: 合計 / 2025年5月2 | F3: 合計 / 2025年6月2 | G3: 合計 / 2025年7月2 | H3: 合計 / 2025年8月2 | I3: 合計 / 2025年9月2 | J3: 合計 / 2025年10月2 | K3: 合計 / 2025年11月2 | L3: 合計 / 2025年12月2 | M3: 合計 / 2026年1月2 | N3: 合計 / 2026年2月2 | O3: 合計 / 2026年3月 | P3: 合計 / 2026年4月 | Q3: 合計 / 2026年5月 | R3: 合計 / 2026年6月 | S3: 合計 / 2026年7月 | T3: 合計 / 2026年8月 | U3: 合計 / 2026年9月 | V3: 合計 / 2026年10月 | W3: 合計 / 2026年11月 | X3: 合計 / 2026年12月 | Y3: 合計 / 2027年1月
A4: 3ヶ月会員（ライト・クレカ自動更新） | B4: 19800 | C4: 1821600 | D4: 2296800 | E4: 2296800 | F4: 495000 | G4: 19800
A5: 6ヶ月会員（ライト・クレカ自動更新） | B5: 38100 | C5: 533400 | D5: 3009900 | E5: 3181350 | F5: 9353550 | G5: 9467850 | H5: 9448800 | I5: 8953500 | J5: 6477000 | K5: 6305550 | L5: 133350 | M5: 19050
A6: Apex年間会員（自動更新） | D6: 56610 | E6: 84915 | F6: 84915 | G6: 94350 | H6: 245310 | I6: 245310 | J6: 245310 | K6: 245310 | L6: 254745 | M6: 254745 | N6: 349095 | O6: 349095 | P6: 292485 | Q6: 264180 | R6: 264180 | S6: 254745 | T6: 103785 | U6: 103785 | V6: 103785 | W6: 103785 | X6: 94350 | Y6: 94350
A7: 銀振会員（更新要ｶｸﾆﾝ）3ヶ月 | C7: 178200 | D7: 198000 | E7: 198000 | F7: 19800
A8: 銀振会員（更新要ｶｸﾆﾝ）6ヶ月 | D8: 76200 | E8: 76200 | F8: 495300 | G8: 495300 | H8: 495300 | I8: 495300 | J8: 419100 | K8: 419100
A9: 総計 | B9: 57900 | C9: 2533200 | D9: 5637510 | E9: 5837265 | F9: 10448565 | G9: 10077300 | H9: 10189410 | I9: 9694110 | J9: 7141410 | K9: 6969960 | L9: 388095 | M9: 273795 | N9: 349095 | O9: 349095 | P9: 292485 | Q9: 264180 | R9: 264180 | S9: 254745 | T9: 103785 | U9: 103785 | V9: 103785 | W9: 103785 | X9: 94350 | Y9: 94350
A18: 氏名 | B18: (複数のアイテム)
A20: 行ラベル | B20: 合計 / 2025年2月 | C20: 合計 / 2025年3月 | D20: 合計 / 2025年4月 | E20: 合計 / 2025年5月 | F20: 合計 / 2025年6月 | G20: 合計 / 2025年7月 | H20: 合計 / 2025年8月 | I20: 合計 / 2025年9月 | J20: 合計 / 2025年10月 | K20: 合計 / 2025年11月 | L20: 合計 / 2025年12月 | M20: 合計 / 2026年1月 | N20: 合計 / 2026年2月
A21: 3ヶ月会員（ライト・クレカ自動更新） | B21: 59400 | C21: 5405400 | D21: 1425600 | E21: 59400 | F21: 0 | G21: 0 | H21: 0 | I21: 0 | J21: 0 | K21: 0 | L21: 0 | M21: 0 | N21: 0
A22: 6ヶ月会員（ライト・クレカ自動更新） | B22: 228600 | C22: 2971800 | D22: 14859000 | E22: 1028700 | F22: 37033200 | G22: 685800 | H22: 114300 | I22: 0 | J22: 0 | K22: 0 | L22: 0 | M22: 0 | N22: 0
A23: Apex年間会員（自動更新） | B23: 0 | C23: 0 | D23: 679320 | E23: 339660 | F23: 0 | G23: 113220 | H23: 1811520 | I23: 0 | J23: 0 | K23: 0 | L23: 113220 | M23: 0 | N23: 1132200
A24: 銀振会員（更新要ｶｸﾆﾝ）3ヶ月 | B24: 0 | C24: 534600 | D24: 59400 | E24: 0 | F24: 0 | G24: 0 | H24: 0 | I24: 0 | J24: 0 | K24: 0 | L24: 0 | M24: 0 | N24: 0
A25: 銀振会員（更新要ｶｸﾆﾝ）6ヶ月 | B25: 0 | C25: 0 | D25: 457200 | E25: 0 | F25: 2514600 | G25: 0 | H25: 0 | I25: 0 | J25: 0 | K25: 0 | L25: 0 | M25: 0 | N25: 0
A26: 総計 | B26: 288000 | C26: 8911800 | D26: 17480520 | E26: 1427760 | F26: 39547800 | G26: 799020 | H26: 1925820 | I26: 0 | J26: 0 | K26: 0 | L26: 113220 | M26: 0 | N26: 1132200
A33: 分割計上後
A34: 行ラベル | B34: 3ヶ月会員（ライト・クレカ自動更新） | C34: 6ヶ月会員（ライト・クレカ自動更新） | D34: Apex年間会員（自動更新） | E34: 銀振会員（更新要ｶｸﾆﾝ）3ヶ月 | F34: 銀振会員（更新要ｶｸﾆﾝ）6ヶ月 | G34: 総計
A35: 45689 | B35: 19800 | C35: 38100 | G35: 57900
A36: 45717 | B36: 1821600 | C36: 533400 | E36: 178200 | G36: 2533200
A37: 45748 | B37: 2296800 | C37: 3009900 | D37: 56610 | E37: 198000 | F37: 76200 | G37: 5637510
A38: 45778 | B38: 2296800 | C38: 3181350 | D38: 84915 | E38: 198000 | F38: 76200 | G38: 5837265
A39: 45809 | B39: 495000 | C39: 9353550 | D39: 84915 | E39: 19800 | F39: 495300 | G39: 10448565
A40: 45839 | B40: 19800 | C40: 9467850 | D40: 94350 | F40: 495300 | G40: 10077300
A41: 45870 | C41: 9448800 | D41: 245310 | F41: 495300 | G41: 10189410
A42: 45901 | C42: 8953500 | D42: 245310 | F42: 495300 | G42: 9694110
A43: 45931 | C43: 6477000 | D43: 245310 | F43: 419100 | G43: 7141410
A44: 45962 | C44: 6305550 | D44: 245310 | F44: 419100 | G44: 6969960
A45: 45992 | C45: 133350 | D45: 254745 | G45: 388095
A46: 46023 | C46: 19050 | D46: 254745 | G46: 273795
A47: 46054 | D47: 349095 | G47: 349095
A48: 46082 | D48: 349095 | G48: 349095
A49: 46113 | D49: 292485 | G49: 292485
A50: 46143 | D50: 264180 | G50: 264180
A51: 46174 | D51: 264180 | G51: 264180
A52: 46204 | D52: 254745 | G52: 254745
A53: 46235 | D53: 103785 | G53: 103785
A54: 46266 | D54: 103785 | G54: 103785
A55: 46296 | D55: 103785 | G55: 103785
A56: 46327 | D56: 103785 | G56: 103785
...

Sheet まとめ継続(1月)
A1: 新 業務提携者（従属） | B1: 顧客ID | C1: 氏名 | D1: 登録メールアドレス | E1: CLEARTRADEコミュ会員タイプ | F1: CLEARTRADEコミュ入会日 | G1: CLEARTRADEコミュ退会日 | H1: CLEARTRADEコミュ支払方法 | I1: 金額 | J1: CLEARTRADEコミュ配信状況 | K1: 2025年2月 | L1: 2025年3月 | M1: 2025年4月 | N1: 2025年5月 | O1: 2025年6月 | P1: 2025年7月 | Q1: 2025年8月 | R1: 2025年9月 | S1: 2025年10月 | T1: 2025年11月 | U1: 2025年12月 | V1: 2026年1月 | W1: 2026年2月 | X1: 期間 | Y1: 2025年2月 | Z1: 2025年3月 | AA1: 2025年4月 | AB1: 2025年5月 | AC1: 2025年6月 | AD1: 2025年7月 | AE1: 2025年8月 | AF1: 2025年9月 | AG1: 2025年10月 | AH1: 2025年11月 | AI1: 2025年12月 | AJ1: 2026年1月 | AK1: 2026年2月 | AL1: 2026年3月 | AM1: 2026年4月 | AN1: 2026年5月 | AO1: 2026年6月 | AP1: 2026年7月 | AQ1: 2026年8月 | AR1: 2026年9月 | AS1: 2026年10月 | AT1: 2026年11月 | AU1: 2026年12月 | AV1: 2027年1月 | AW1: A | AX1: B | AY1: C | AZ1: D
A2: PEAK ONE. LLC[山崎裕久(Mr.K)] | B2: C-00075126 | C2: 武田祐二 | D2: yellow.tail@docomo.ne.jp | E2: 3ヶ月会員（ライト・クレカ自動更新） | F2: 2025/01/23 00:00:00 | G2: 2025/04/20 00:00:00 | H2: クレジットカード（ROBOT） | I2: 59400 | J2: 1 | K2: 0 | L2: 0 | M2: 59400 | N2: 0 | O2: 0 | P2: 0 | Q2: 0 | R2: 0 | S2: 0 | T2: 0 | U2: 0 | V2: 0 | W2: 0 | X2: 3 | AA2: 19800 | AB2: 19800 | AC2: 19800 | AW2: =+COUNTA(Y2:AV2) -> 3 | AX2: =+AW2=X2 -> TRUE | AY2: =+SUM(Y2:AV2) -> 59400 | AZ2: =+I2=AY2 -> TRUE
A3: PEAK ONE. LLC[山崎裕久(Mr.K)] | B3: C-00074947 | C3: 宮川美樹 | D3: adgjmptw2001@gmail.com | E3: 3ヶ月会員（ライト・クレカ自動更新） | F3: 2024/12/09 00:00:00 | G3: 2025/03/20 00:00:00 | H3: クレジットカード（ROBOT） | I3: 59400 | J3: 2 | K3: 0 | L3: 59400 | M3: 0 | N3: 0 | O3: 0 | P3: 0 | Q3: 0 | R3: 0 | S3: 0 | T3: 0 | U3: 0 | V3: 0 | W3: 0 | X3: 3 | Z3: 19800 | AA3: 19800 | AB3: 19800 | AW3: =+COUNTA(Y3:AV3) -> 3 | AX3: =+AW3=X3 -> TRUE | AY3: =+SUM(Y3:AV3) -> 59400 | AZ3: =+I3=AY3 -> TRUE
